Workbook

Sheet Read me
A1: RESEARCHER ONLY: DO NOT SHARE WITH RATERS
A2: Blinding: in each booklet the original scene is shown as Version A or Version B according to sheet 'Blinding key' (balanced 13 A / 12 B, seed 42).
A3: 1. When a rater file comes back, copy its 'Ratings' cells D3:U27 into the same cells of sheet R1, R2 or R3 (Paste Special > Values), and type the rater's booklet language in cell B30 of that sheet.
A4: 2. 'Features' decodes A/B into original/rewrite for every pair × feature and compares the human means with Qwen. 'Quality' does the same for coherence, acceptability and the Same/Partly/Different items.
A5: 3. 'Summary' shows the main results. Correlations and inter-rater reliability are computed by the analysis script.

Sheet Blinding key
A1: Pair | B1: Pair ID | C1: Film | D1: Task | E1: Scene position | F1: Target feature | G1: Original shown as | H1: Rewrite shown as
A2: 01 | B2: HE-e303ecb81cfd | C2: Ghostbusters II | D2: v5_T0108 | E2: 7 | F2: Dialogue Density | G2: B | H2: A
A3: 02 | B3: HE-cb4843e61769 | C3: Ghostbusters II | D3: v5_T0108 | E3: 9 | F3: Dialogue Density | G3: A | H3: B
A4: 03 | B4: HE-41d39a1b0d34 | C4: Ghostbusters II | D4: v5_T0108 | E4: 1 | F4: Dialogue Density | G4: A | H4: B
A5: 04 | B5: HE-f3e48b301237 | C5: The Private Life of Sherlock Holmes | D5: v5_T0129 | E5: 6 | F5: Action Density | G5: B | H5: A
A6: 05 | B6: HE-9b53a614098d | C6: The Private Life of Sherlock Holmes | D6: v5_T0129 | E6: 7 | F6: Action Density | G6: B | H6: A
A7: 06 | B7: HE-02976e0045d3 | C7: Ghostbusters II | D7: v5_T0108 | E7: 4 | F7: Dialogue Density | G7: A | H7: B
A8: 07 | B8: HE-774e675404e7 | C8: Ghostbusters II | D8: v5_T0108 | E8: 5 | F8: Dialogue Density | G8: A | H8: B
A9: 08 | B9: HE-14dd09a43c06 | C9: Dog Day Afternoon | D9: v5_T0165 | E9: 1 | F9: Character Interaction | G9: A | H9: B
A10: 09 | B10: HE-45a1ac107489 | C10: Ghostbusters II | D10: v5_T0108 | E10: 11 | F10: Dialogue Density | G10: B | H10: A
A11: 10 | B11: HE-6afe294dcb70 | C11: The Private Life of Sherlock Holmes | D11: v5_T0129 | E11: 2 | F11: Action Density | G11: B | H11: A
A12: 11 | B12: HE-dfb1e02458b2 | C12: The Private Life of Sherlock Holmes | D12: v5_T0129 | E12: 5 | F12: Action Density | G12: A | H12: B
A13: 12 | B13: HE-cfb4d616ddee | C13: Dog Day Afternoon | D13: v5_T0165 | E13: 5 | F13: Character Interaction | G13: B | H13: A
... A26: 25 | B26: HE-cc501e92c91a | C26: Ghostbusters II | D26: v5_T0108 | E26: 3 | F26: Dialogue Density | G26: B | H26: A

Sheet R1
A1: Pair | D1: Version A: Features (0-10) | I1: Version B: Features (0-10) | N1: Same / Partly / Different | Q1: Quality (1, 3, 5)
A2: No. | B2: Pair | C2: Pair ID | D2: Pacing | E2: Dialogue | F2: Action | G2: Interaction | H2: Emotion | I2: Pacing | J2: Dialogue | K2: Action | L2: Interaction | M2: Emotion | N2: Characters | O2: Setting | P2: Events | Q2: Coherence A | R2: Coherence B | S2: Acceptability A | T2: Acceptability B | U2: Note
A3: 1 | B3: 01 | C3: HE-e303ecb81cfd
A4: 2 | B4: 02 | C4: HE-cb4843e61769
A5: 3 | B5: 03 | C5: HE-41d39a1b0d34
A6: 4 | B6: 04 | C6: HE-f3e48b301237
A7: 5 | B7: 05 | C7: HE-9b53a614098d
A8: 6 | B8: 06 | C8: HE-02976e0045d3
A9: 7 | B9: 07 | C9: HE-774e675404e7
A10: 8 | B10: 08 | C10: HE-14dd09a43c06
A11: 9 | B11: 09 | C11: HE-45a1ac107489
A12: 10 | B12: 10 | C12: HE-6afe294dcb70
A13: 11 | B13: 11 | C13: HE-dfb1e02458b2
A14: 12 | B14: 12 | C14: HE-cfb4d616ddee
... A27: 25 | B27: 25 | C27: HE-cc501e92c91a
A30: Booklet language

Sheet R2
A1: Pair | D1: Version A: Features (0-10) | I1: Version B: Features (0-10) | N1: Same / Partly / Different | Q1: Quality (1, 3, 5)
A2: No. | B2: Pair | C2: Pair ID | D2: Pacing | E2: Dialogue | F2: Action | G2: Interaction | H2: Emotion | I2: Pacing | J2: Dialogue | K2: Action | L2: Interaction | M2: Emotion | N2: Characters | O2: Setting | P2: Events | Q2: Coherence A | R2: Coherence B | S2: Acceptability A | T2: Acceptability B | U2: Note
A3: 1 | B3: 01 | C3: HE-e303ecb81cfd
A4: 2 | B4: 02 | C4: HE-cb4843e61769
A5: 3 | B5: 03 | C5: HE-41d39a1b0d34
A6: 4 | B6: 04 | C6: HE-f3e48b301237
A7: 5 | B7: 05 | C7: HE-9b53a614098d
A8: 6 | B8: 06 | C8: HE-02976e0045d3
A9: 7 | B9: 07 | C9: HE-774e675404e7
A10: 8 | B10: 08 | C10: HE-14dd09a43c06
A11: 9 | B11: 09 | C11: HE-45a1ac107489
A12: 10 | B12: 10 | C12: HE-6afe294dcb70
A13: 11 | B13: 11 | C13: HE-dfb1e02458b2
A14: 12 | B14: 12 | C14: HE-cfb4d616ddee
... A27: 25 | B27: 25 | C27: HE-cc501e92c91a
A30: Booklet language

Sheet R3
A1: Pair | D1: Version A: Features (0-10) | I1: Version B: Features (0-10) | N1: Same / Partly / Different | Q1: Quality (1, 3, 5)
A2: No. | B2: Pair | C2: Pair ID | D2: Pacing | E2: Dialogue | F2: Action | G2: Interaction | H2: Emotion | I2: Pacing | J2: Dialogue | K2: Action | L2: Interaction | M2: Emotion | N2: Characters | O2: Setting | P2: Events | Q2: Coherence A | R2: Coherence B | S2: Acceptability A | T2: Acceptability B | U2: Note
A3: 1 | B3: 01 | C3: HE-e303ecb81cfd
A4: 2 | B4: 02 | C4: HE-cb4843e61769
A5: 3 | B5: 03 | C5: HE-41d39a1b0d34
A6: 4 | B6: 04 | C6: HE-f3e48b301237
A7: 5 | B7: 05 | C7: HE-9b53a614098d
A8: 6 | B8: 06 | C8: HE-02976e0045d3
A9: 7 | B9: 07 | C9: HE-774e675404e7
A10: 8 | B10: 08 | C10: HE-14dd09a43c06
A11: 9 | B11: 09 | C11: HE-45a1ac107489
A12: 10 | B12: 10 | C12: HE-6afe294dcb70
A13: 11 | B13: 11 | C13: HE-dfb1e02458b2
A14: 12 | B14: 12 | C14: HE-cfb4d616ddee
... A27: 25 | B27: 25 | C27: HE-cc501e92c91a
A30: Booklet language

Sheet Features
A1: No. | B1: Pair | C1: Pair ID | D1: Film | E1: Feature | F1: Feat # | G1: Target feature | H1: Target | I1: Qwen Original | J1: Qwen Rewrite | K1: Qwen change | L1: Original shown as | M1: Human Original (mean) | N1: Human Rewrite (mean) | O1: Human change | P1: Direction agrees (1/0) | Q1: Human toward target (1/0) | R1: Qwen toward target (1/0)
A2: 1 | B2: 1 | C2: HE-e303ecb81cfd | D2: Ghostbusters II | E2: Pacing | F2: 1 | I2: 0.6 | J2: 0.6 | K2: =J2-I2 -> 0 | L2: =VLOOKUP(TEXT(B2,"00"),'Blinding key'!$A$2:$G$26,7,FALSE()) -> B | M2: =IFERROR(AVERAGE(INDEX('R1'!$D$3:$M$27,$B2,IF($L2="A",$F2,$F2+5)),INDEX('R2'!$D$3:$M$27,$B2,IF($L2="A",$F2,$F2+5)),INDEX('R3'!$D$3:$M$27,$B2,IF($L2="A",$F2,$F2+5))),"") | N2: =IFERROR(AVERAGE(INDEX('R1'!$D$3:$M$27,$B2,IF($L2="A",$F2+5,$F2)),INDEX('R2'!$D$3:$M$27,$B2,IF($L2="A",$F2+5,$F2)),INDEX('R3'!$D$3:$M$27,$B2,IF($L2="A",$F2+5,$F2))),"") | O2: =IF(OR(M2="",N2=""),"",N2-M2) | P2: =IF(O2="","",IF(SIGN(ROUND(O2,6))=SIGN(ROUND(K2,6)),1,0)) | Q2: =IF(OR(G2<>"Y",O2=""),"",IF(SIGN(ROUND(O2,6))=SIGN(ROUND(H2-I2,6)),1,0)) | R2: =IF(G2<>"Y","",IF(SIGN(ROUND(K2,6))=SIGN(ROUND(H2-I2,6)),1,0))
A3: 2 | B3: 1 | C3: HE-e303ecb81cfd | D3: Ghostbusters II | E3: Dialogue Density | F3: 2 | G3: Y | H3: 0.3 | I3: 0.8 | J3: 0.4 | K3: =J3-I3 -> -0.4 | L3: =VLOOKUP(TEXT(B3,"00"),'Blinding key'!$A$2:$G$26,7,FALSE()) -> B | M3: =IFERROR(AVERAGE(INDEX('R1'!$D$3:$M$27,$B3,IF($L3="A",$F3,$F3+5)),INDEX('R2'!$D$3:$M$27,$B3,IF($L3="A",$F3,$F3+5)),INDEX('R3'!$D$3:$M$27,$B3,IF($L3="A",$F3,$F3+5))),"") | N3: =IFERROR(AVERAGE(INDEX('R1'!$D$3:$M$27,$B3,IF($L3="A",$F3+5,$F3)),INDEX('R2'!$D$3:$M$27,$B3,IF($L3="A",$F3+5,$F3)),INDEX('R3'!$D$3:$M$27,$B3,IF($L3="A",$F3+5,$F3))),"") | O3: =IF(OR(M3="",N3=""),"",N3-M3) | P3: =IF(O3="","",IF(SIGN(ROUND(O3,6))=SIGN(ROUND(K3,6)),1,0)) | Q3: =IF(OR(G3<>"Y",O3=""),"",IF(SIGN(ROUND(O3,6))=SIGN(ROUND(H3-I3,6)),1,0)) | R3: =IF(G3<>"Y","",IF(SIGN(ROUND(K3,6))=SIGN(ROUND(H3-I3,6)),1,0)) -> 1
A4: 3 | B4: 1 | C4: HE-e303ecb81cfd | D4: Ghostbusters II | E4: Action Density | F4: 3 | I4: 0.4 | J4: 0.3 | K4: =J4-I4 -> -0.1 | L4: =VLOOKUP(TEXT(B4,"00"),'Blinding key'!$A$2:$G$26,7,FALSE()) -> B | M4: =IFERROR(AVERAGE(INDEX('R1'!$D$3:$M$27,$B4,IF($L4="A",$F4,$F4+5)),INDEX('R2'!$D$3:$M$27,$B4,IF($L4="A",$F4,$F4+5)),INDEX('R3'!$D$3:$M$27,$B4,IF($L4="A",$F4,$F4+5))),"") | N4: =IFERROR(AVERAGE(INDEX('R1'!$D$3:$M$27,$B4,IF($L4="A",$F4+5,$F4)),INDEX('R2'!$D$3:$M$27,$B4,IF($L4="A",$F4+5,$F4)),INDEX('R3'!$D$3:$M$27,$B4,IF($L4="A",$F4+5,$F4))),"") | O4: =IF(OR(M4="",N4=""),"",N4-M4) | P4: =IF(O4="","",IF(SIGN(ROUND(O4,6))=SIGN(ROUND(K4,6)),1,0)) | Q4: =IF(OR(G4<>"Y",O4=""),"",IF(SIGN(ROUND(O4,6))=SIGN(ROUND(H4-I4,6)),1,0)) | R4: =IF(G4<>"Y","",IF(SIGN(ROUND(K4,6))=SIGN(ROUND(H4-I4,6)),1,0))
A5: 4 | B5: 1 | C5: HE-e303ecb81cfd | D5: Ghostbusters II | E5: Character Interaction | F5: 4 | I5: 0.9 | J5: 0.5 | K5: =J5-I5 -> -0.4 | L5: =VLOOKUP(TEXT(B5,"00"),'Blinding key'!$A$2:$G$26,7,FALSE()) -> B | M5: =IFERROR(AVERAGE(INDEX('R1'!$D$3:$M$27,$B5,IF($L5="A",$F5,$F5+5)),INDEX('R2'!$D$3:$M$27,$B5,IF($L5="A",$F5,$F5+5)),INDEX('R3'!$D$3:$M$27,$B5,IF($L5="A",$F5,$F5+5))),"") | N5: =IFERROR(AVERAGE(INDEX('R1'!$D$3:$M$27,$B5,IF($L5="A",$F5+5,$F5)),INDEX('R2'!$D$3:$M$27,$B5,IF($L5="A",$F5+5,$F5)),INDEX('R3'!$D$3:$M$27,$B5,IF($L5="A",$F5+5,$F5))),"") | O5: =IF(OR(M5="",N5=""),"",N5-M5) | P5: =IF(O5="","",IF(SIGN(ROUND(O5,6))=SIGN(ROUND(K5,6)),1,0)) | Q5: =IF(OR(G5<>"Y",O5=""),"",IF(SIGN(ROUND(O5,6))=SIGN(ROUND(H5-I5,6)),1,0)) | R5: =IF(G5<>"Y","",IF(SIGN(ROUND(K5,6))=SIGN(ROUND(H5-I5,6)),1,0))
A6: 5 | B6: 1 | C6: HE-e303ecb81cfd | D6: Ghostbusters II | E6: Emotion Intensity | F6: 5 | I6: 0.3 | J6: 0.2 | K6: =J6-I6 -> -0.1 | L6: =VLOOKUP(TEXT(B6,"00"),'Blinding key'!$A$2:$G$26,7,FALSE()) -> B | M6: =IFERROR(AVERAGE(INDEX('R1'!$D$3:$M$27,$B6,IF($L6="A",$F6,$F6+5)),INDEX('R2'!$D$3:$M$27,$B6,IF($L6="A",$F6,$F6+5)),INDEX('R3'!$D$3:$M$27,$B6,IF($L6="A",$F6,$F6+5))),"") | N6: =IFERROR(AVERAGE(INDEX('R1'!$D$3:$M$27,$B6,IF($L6="A",$F6+5,$F6)),INDEX('R2'!$D$3:$M$27,$B6,IF($L6="A",$F6+5,$F6)),INDEX('R3'!$D$3:$M$27,$B6,IF($L6="A",$F6+5,$F6))),"") | O6: =IF(OR(M6="",N6=""),"",N6-M6) | P6: =IF(O6="","",IF(SIGN(ROUND(O6,6))=SIGN(ROUND(K6,6)),1,0)) | Q6: =IF(OR(G6<>"Y",O6=""),"",IF(SIGN(ROUND(O6,6))=SIGN(ROUND(H6-I6,6)),1,0)) | R6: =IF(G6<>"Y","",IF(SIGN(ROUND(K6,6))=SIGN(ROUND(H6-I6,6)),1,0))
A7: 6 | B7: 2 | C7: HE-cb4843e61769 | D7: Ghostbusters II | E7: Pacing | F7: 1 | I7: 0.5 | J7: 0.7 | K7: =J7-I7 -> 0.2 | L7: =VLOOKUP(TEXT(B7,"00"),'Blinding key'!$A$2:$G$26,7,FALSE()) -> A | M7: =IFERROR(AVERAGE(INDEX('R1'!$D$3:$M$27,$B7,IF($L7="A",$F7,$F7+5)),INDEX('R2'!$D$3:$M$27,$B7,IF($L7="A",$F7,$F7+5)),INDEX('R3'!$D$3:$M$27,$B7,IF($L7="A",$F7,$F7+5))),"") | N7: =IFERROR(AVERAGE(INDEX('R1'!$D$3:$M$27,$B7,IF($L7="A",$F7+5,$F7)),INDEX('R2'!$D$3:$M$27,$B7,IF($L7="A",$F7+5,$F7)),INDEX('R3'!$D$3:$M$27,$B7,IF($L7="A",$F7+5,$F7))),"") | O7: =IF(OR(M7="",N7=""),"",N7-M7) | P7: =IF(O7="","",IF(SIGN(ROUND(O7,6))=SIGN(ROUND(K7,6)),1,0)) | Q7: =IF(OR(G7<>"Y",O7=""),"",IF(SIGN(ROUND(O7,6))=SIGN(ROUND(H7-I7,6)),1,0)) | R7: =IF(G7<>"Y","",IF(SIGN(ROUND(K7,6))=SIGN(ROUND(H7-I7,6)),1,0))
A8: 7 | B8: 2 | C8: HE-cb4843e61769 | D8: Ghostbusters II | E8: Dialogue Density | F8: 2 | G8: Y | H8: 0.8 | I8: 0 | J8: 0.8 | K8: =J8-I8 -> 0.8 | L8: =VLOOKUP(TEXT(B8,"00"),'Blinding key'!$A$2:$G$26,7,FALSE()) -> A | M8: =IFERROR(AVERAGE(INDEX('R1'!$D$3:$M$27,$B8,IF($L8="A",$F8,$F8+5)),INDEX('R2'!$D$3:$M$27,$B8,IF($L8="A",$F8,$F8+5)),INDEX('R3'!$D$3:$M$27,$B8,IF($L8="A",$F8,$F8+5))),"") | N8: =IFERROR(AVERAGE(INDEX('R1'!$D$3:$M$27,$B8,IF($L8="A",$F8+5,$F8)),INDEX('R2'!$D$3:$M$27,$B8,IF($L8="A",$F8+5,$F8)),INDEX('R3'!$D$3:$M$27,$B8,IF($L8="A",$F8+5,$F8))),"") | O8: =IF(OR(M8="",N8=""),"",N8-M8) | P8: =IF(O8="","",IF(SIGN(ROUND(O8,6))=SIGN(ROUND(K8,6)),1,0)) | Q8: =IF(OR(G8<>"Y",O8=""),"",IF(SIGN(ROUND(O8,6))=SIGN(ROUND(H8-I8,6)),1,0)) | R8: =IF(G8<>"Y","",IF(SIGN(ROUND(K8,6))=SIGN(ROUND(H8-I8,6)),1,0)) -> 1
A9: 8 | B9: 2 | C9: HE-cb4843e61769 | D9: Ghostbusters II | E9: Action Density | F9: 3 | I9: 1 | J9: 0.5 | K9: =J9-I9 -> -0.5 | L9: =VLOOKUP(TEXT(B9,"00"),'Blinding key'!$A$2:$G$26,7,FALSE()) -> A | M9: =IFERROR(AVERAGE(INDEX('R1'!$D$3:$M$27,$B9,IF($L9="A",$F9,$F9+5)),INDEX('R2'!$D$3:$M$27,$B9,IF($L9="A",$F9,$F9+5)),INDEX('R3'!$D$3:$M$27,$B9,IF($L9="A",$F9,$F9+5))),"") | N9: =IFERROR(AVERAGE(INDEX('R1'!$D$3:$M$27,$B9,IF($L9="A",$F9+5,$F9)),INDEX('R2'!$D$3:$M$27,$B9,IF($L9="A",$F9+5,$F9)),INDEX('R3'!$D$3:$M$27,$B9,IF($L9="A",$F9+5,$F9))),"") | O9: =IF(OR(M9="",N9=""),"",N9-M9) | P9: =IF(O9="","",IF(SIGN(ROUND(O9,6))=SIGN(ROUND(K9,6)),1,0)) | Q9: =IF(OR(G9<>"Y",O9=""),"",IF(SIGN(ROUND(O9,6))=SIGN(ROUND(H9-I9,6)),1,0)) | R9: =IF(G9<>"Y","",IF(SIGN(ROUND(K9,6))=SIGN(ROUND(H9-I9,6)),1,0))
A10: 9 | B10: 2 | C10: HE-cb4843e61769 | D10: Ghostbusters II | E10: Character Interaction | F10: 4 | I10: 0 | J10: 0.9 | K10: =J10-I10 -> 0.9 | L10: =VLOOKUP(TEXT(B10,"00"),'Blinding key'!$A$2:$G$26,7,FALSE()) -> A | M10: =IFERROR(AVERAGE(INDEX('R1'!$D$3:$M$27,$B10,IF($L10="A",$F10,$F10+5)),INDEX('R2'!$D$3:$M$27,$B10,IF($L10="A",$F10,$F10+5)),INDEX('R3'!$D$3:$M$27,$B10,IF($L10="A",$F10,$F10+5))),"") | N10: =IFERROR(AVERAGE(INDEX('R1'!$D$3:$M$27,$B10,IF($L10="A",$F10+5,$F10)),INDEX('R2'!$D$3:$M$27,$B10,IF($L10="A",$F10+5,$F10)),INDEX('R3'!$D$3:$M$27,$B10,IF($L10="A",$F10+5,$F10))),"") | O10: =IF(OR(M10="",N10=""),"",N10-M10) | P10: =IF(O10="","",IF(SIGN(ROUND(O10,6))=SIGN(ROUND(K10,6)),1,0)) | Q10: =IF(OR(G10<>"Y",O10=""),"",IF(SIGN(ROUND(O10,6))=SIGN(ROUND(H10-I10,6)),1,0)) | R10: =IF(G10<>"Y","",IF(SIGN(ROUND(K10,6))=SIGN(ROUND(H10-I10,6)),1,0))
A11: 10 | B11: 2 | C11: HE-cb4843e61769 | D11: Ghostbusters II | E11: Emotion Intensity | F11: 5 | I11: 0.3 | J11: 0.6 | K11: =J11-I11 -> 0.3 | L11: =VLOOKUP(TEXT(B11,"00"),'Blinding key'!$A$2:$G$26,7,FALSE()) -> A | M11: =IFERROR(AVERAGE(INDEX('R1'!$D$3:$M$27,$B11,IF($L11="A",$F11,$F11+5)),INDEX('R2'!$D$3:$M$27,$B11,IF($L11="A",$F11,$F11+5)),INDEX('R3'!$D$3:$M$27,$B11,IF($L11="A",$F11,$F11+5))),"") | N11: =IFERROR(AVERAGE(INDEX('R1'!$D$3:$M$27,$B11,IF($L11="A",$F11+5,$F11)),INDEX('R2'!$D$3:$M$27,$B11,IF($L11="A",$F11+5,$F11)),INDEX('R3'!$D$3:$M$27,$B11,IF($L11="A",$F11+5,$F11))),"") | O11: =IF(OR(M11="",N11=""),"",N11-M11) | P11: =IF(O11="","",IF(SIGN(ROUND(O11,6))=SIGN(ROUND(K11,6)),1,0)) | Q11: =IF(OR(G11<>"Y",O11=""),"",IF(SIGN(ROUND(O11,6))=SIGN(ROUND(H11-I11,6)),1,0)) | R11: =IF(G11<>"Y","",IF(SIGN(ROUND(K11,6))=SIGN(ROUND(H11-I11,6)),1,0))
A12: 11 | B12: 3 | C12: HE-41d39a1b0d34 | D12: Ghostbusters II | E12: Pacing | F12: 1 | I12: 0.6 | J12: 0.6 | K12: =J12-I12 -> 0 | L12: =VLOOKUP(TEXT(B12,"00"),'Blinding key'!$A$2:$G$26,7,FALSE()) -> A | M12: =IFERROR(AVERAGE(INDEX('R1'!$D$3:$M$27,$B12,IF($L12="A",$F12,$F12+5)),INDEX('R2'!$D$3:$M$27,$B12,IF($L12="A",$F12,$F12+5)),INDEX('R3'!$D$3:$M$27,$B12,IF($L12="A",$F12,$F12+5))),"") | N12: =IFERROR(AVERAGE(INDEX('R1'!$D$3:$M$27,$B12,IF($L12="A",$F12+5,$F12)),INDEX('R2'!$D$3:$M$27,$B12,IF($L12="A",$F12+5,$F12)),INDEX('R3'!$D$3:$M$27,$B12,IF($L12="A",$F12+5,$F12))),"") | O12: =IF(OR(M12="",N12=""),"",N12-M12) | P12: =IF(O12="","",IF(SIGN(ROUND(O12,6))=SIGN(ROUND(K12,6)),1,0)) | Q12: =IF(OR(G12<>"Y",O12=""),"",IF(SIGN(ROUND(O12,6))=SIGN(ROUND(H12-I12,6)),1,0)) | R12: =IF(G12<>"Y","",IF(SIGN(ROUND(K12,6))=SIGN(ROUND(H12-I12,6)),1,0))
A13: 12 | B13: 3 | C13: HE-41d39a1b0d34 | D13: Ghostbusters II | E13: Dialogue Density | F13: 2 | G13: Y | H13: 0.4 | I13: 0.4 | J13: 0.4 | K13: =J13-I13 -> 0 | L13: =VLOOKUP(TEXT(B13,"00"),'Blinding key'!$A$2:$G$26,7,FALSE()) -> A | M13: =IFERROR(AVERAGE(INDEX('R1'!$D$3:$M$27,$B13,IF($L13="A",$F13,$F13+5)),INDEX('R2'!$D$3:$M$27,$B13,IF($L13="A",$F13,$F13+5)),INDEX('R3'!$D$3:$M$27,$B13,IF($L13="A",$F13,$F13+5))),"") | N13: =IFERROR(AVERAGE(INDEX('R1'!$D$3:$M$27,$B13,IF($L13="A",$F13+5,$F13)),INDEX('R2'!$D$3:$M$27,$B13,IF($L13="A",$F13+5,$F13)),INDEX('R3'!$D$3:$M$27,$B13,IF($L13="A",$F13+5,$F13))),"") | O13: =IF(OR(M13="",N13=""),"",N13-M13) | P13: =IF(O13="","",IF(SIGN(ROUND(O13,6))=SIGN(ROUND(K13,6)),1,0)) | Q13: =IF(OR(G13<>"Y",O13=""),"",IF(SIGN(ROUND(O13,6))=SIGN(ROUND(H13-I13,6)),1,0)) | R13: =IF(G13<>"Y","",IF(SIGN(ROUND(K13,6))=SIGN(ROUND(H13-I13,6)),1,0)) -> 1
A14: 13 | B14: 3 | C14: HE-41d39a1b0d34 | D14: Ghostbusters II | E14: Action Density | F14: 3 | I14: 0.8 | J14: 0.8 | K14: =J14-I14 -> 0 | L14: =VLOOKUP(TEXT(B14,"00"),'Blinding key'!$A$2:$G$26,7,FALSE()) -> A | M14: =IFERROR(AVERAGE(INDEX('R1'!$D$3:$M$27,$B14,IF($L14="A",$F14,$F14+5)),INDEX('R2'!$D$3:$M$27,$B14,IF($L14="A",$F14,$F14+5)),INDEX('R3'!$D$3:$M$27,$B14,IF($L14="A",$F14,$F14+5))),"") | N14: =IFERROR(AVERAGE(INDEX('R1'!$D$3:$M$27,$B14,IF($L14="A",$F14+5,$F14)),INDEX('R2'!$D$3:$M$27,$B14,IF($L14="A",$F14+5,$F14)),INDEX('R3'!$D$3:$M$27,$B14,IF($L14="A",$F14+5,$F14))),"") | O14: =IF(OR(M14="",N14=""),"",N14-M14) | P14: =IF(O14="","",IF(SIGN(ROUND(O14,6))=SIGN(ROUND(K14,6)),1,0)) | Q14: =IF(OR(G14<>"Y",O14=""),"",IF(SIGN(ROUND(O14,6))=SIGN(ROUND(H14-I14,6)),1,0)) | R14: =IF(G14<>"Y","",IF(SIGN(ROUND(K14,6))=SIGN(ROUND(H14-I14,6)),1,0))
A15: 14 | B15: 3 | C15: HE-41d39a1b0d34 | D15: Ghostbusters II | E15: Character Interaction | F15: 4 | I15: 0.2 | J15: 0.2 | K15: =J15-I15 -> 0 | L15: =VLOOKUP(TEXT(B15,"00"),'Blinding key'!$A$2:$G$26,7,FALSE()) -> A | M15: =IFERROR(AVERAGE(INDEX('R1'!$D$3:$M$27,$B15,IF($L15="A",$F15,$F15+5)),INDEX('R2'!$D$3:$M$27,$B15,IF($L15="A",$F15,$F15+5)),INDEX('R3'!$D$3:$M$27,$B15,IF($L15="A",$F15,$F15+5))),"") | N15: =IFERROR(AVERAGE(INDEX('R1'!$D$3:$M$27,$B15,IF($L15="A",$F15+5,$F15)),INDEX('R2'!$D$3:$M$27,$B15,IF($L15="A",$F15+5,$F15)),INDEX('R3'!$D$3:$M$27,$B15,IF($L15="A",$F15+5,$F15))),"") | O15: =IF(OR(M15="",N15=""),"",N15-M15) | P15: =IF(O15="","",IF(SIGN(ROUND(O15,6))=SIGN(ROUND(K15,6)),1,0)) | Q15: =IF(OR(G15<>"Y",O15=""),"",IF(SIGN(ROUND(O15,6))=SIGN(ROUND(H15-I15,6)),1,0)) | R15: =IF(G15<>"Y","",IF(SIGN(ROUND(K15,6))=SIGN(ROUND(H15-I15,6)),1,0))
A16: 15 | B16: 3 | C16: HE-41d39a1b0d34 | D16: Ghostbusters II | E16: Emotion Intensity | F16: 5 | I16: 0.3 | J16: 0.3 | K16: =J16-I16 -> 0 | L16: =VLOOKUP(TEXT(B16,"00"),'Blinding key'!$A$2:$G$26,7,FALSE()) -> A | M16: =IFERROR(AVERAGE(INDEX('R1'!$D$3:$M$27,$B16,IF($L16="A",$F16,$F16+5)),INDEX('R2'!$D$3:$M$27,$B16,IF($L16="A",$F16,$F16+5)),INDEX('R3'!$D$3:$M$27,$B16,IF($L16="A",$F16,$F16+5))),"") | N16: =IFERROR(AVERAGE(INDEX('R1'!$D$3:$M$27,$B16,IF($L16="A",$F16+5,$F16)),INDEX('R2'!$D$3:$M$27,$B16,IF($L16="A",$F16+5,$F16)),INDEX('R3'!$D$3:$M$27,$B16,IF($L16="A",$F16+5,$F16))),"") | O16: =IF(OR(M16="",N16=""),"",N16-M16) | P16: =IF(O16="","",IF(SIGN(ROUND(O16,6))=SIGN(ROUND(K16,6)),1,0)) | Q16: =IF(OR(G16<>"Y",O16=""),"",IF(SIGN(ROUND(O16,6))=SIGN(ROUND(H16-I16,6)),1,0)) | R16: =IF(G16<>"Y","",IF(SIGN(ROUND(K16,6))=SIGN(ROUND(H16-I16,6)),1,0))
A17: 16 | B17: 4 | C17: HE-f3e48b301237 | D17: The Private Life of Sherlock Holmes | E17: Pacing | F17: 1 | I17: 0.5 | J17: 0.7 | K17: =J17-I17 -> 0.2 | L17: =VLOOKUP(TEXT(B17,"00"),'Blinding key'!$A$2:$G$26,7,FALSE()) -> B | M17: =IFERROR(AVERAGE(INDEX('R1'!$D$3:$M$27,$B17,IF($L17="A",$F17,$F17+5)),INDEX('R2'!$D$3:$M$27,$B17,IF($L17="A",$F17,$F17+5)),INDEX('R3'!$D$3:$M$27,$B17,IF($L17="A",$F17,$F17+5))),"") | N17: =IFERROR(AVERAGE(INDEX('R1'!$D$3:$M$27,$B17,IF($L17="A",$F17+5,$F17)),INDEX('R2'!$D$3:$M$27,$B17,IF($L17="A",$F17+5,$F17)),INDEX('R3'!$D$3:$M$27,$B17,IF($L17="A",$F17+5,$F17))),"") | O17: =IF(OR(M17="",N17=""),"",N17-M17) | P17: =IF(O17="","",IF(SIGN(ROUND(O17,6))=SIGN(ROUND(K17,6)),1,0)) | Q17: =IF(OR(G17<>"Y",O17=""),"",IF(SIGN(ROUND(O17,6))=SIGN(ROUND(H17-I17,6)),1,0)) | R17: =IF(G17<>"Y","",IF(SIGN(ROUND(K17,6))=SIGN(ROUND(H17-I17,6)),1,0))
A18: 17 | B18: 4 | C18: HE-f3e48b301237 | D18: The Private Life of Sherlock Holmes | E18: Dialogue Density | F18: 2 | I18: 0.2 | J18: 0.3 | K18: =J18-I18 -> 0.1 | L18: =VLOOKUP(TEXT(B18,"00"),'Blinding key'!$A$2:$G$26,7,FALSE()) -> B | M18: =IFERROR(AVERAGE(INDEX('R1'!$D$3:$M$27,$B18,IF($L18="A",$F18,$F18+5)),INDEX('R2'!$D$3:$M$27,$B18,IF($L18="A",$F18,$F18+5)),INDEX('R3'!$D$3:$M$27,$B18,IF($L18="A",$F18,$F18+5))),"") | N18: =IFERROR(AVERAGE(INDEX('R1'!$D$3:$M$27,$B18,IF($L18="A",$F18+5,$F18)),INDEX('R2'!$D$3:$M$27,$B18,IF($L18="A",$F18+5,$F18)),INDEX('R3'!$D$3:$M$27,$B18,IF($L18="A",$F18+5,$F18))),"") | O18: =IF(OR(M18="",N18=""),"",N18-M18) | P18: =IF(O18="","",IF(SIGN(ROUND(O18,6))=SIGN(ROUND(K18,6)),1,0)) | Q18: =IF(OR(G18<>"Y",O18=""),"",IF(SIGN(ROUND(O18,6))=SIGN(ROUND(H18-I18,6)),1,0)) | R18: =IF(G18<>"Y","",IF(SIGN(ROUND(K18,6))=SIGN(ROUND(H18-I18,6)),1,0))
A19: 18 | B19: 4 | C19: HE-f3e48b301237 | D19: The Private Life of Sherlock Holmes | E19: Action Density | F19: 3 | G19: Y | H19: 0.9 | I19: 0.1 | J19: 0.6 | K19: =J19-I19 -> 0.5 | L19: =VLOOKUP(TEXT(B19,"00"),'Blinding key'!$A$2:$G$26,7,FALSE()) -> B | M19: =IFERROR(AVERAGE(INDEX('R1'!$D$3:$M$27,$B19,IF($L19="A",$F19,$F19+5)),INDEX('R2'!$D$3:$M$27,$B19,IF($L19="A",$F19,$F19+5)),INDEX('R3'!$D$3:$M$27,$B19,IF($L19="A",$F19,$F19+5))),"") | N19: =IFERROR(AVERAGE(INDEX('R1'!$D$3:$M$27,$B19,IF($L19="A",$F19+5,$F19)),INDEX('R2'!$D$3:$M$27,$B19,IF($L19="A",$F19+5,$F19)),INDEX('R3'!$D$3:$M$27,$B19,IF($L19="A",$F19+5,$F19))),"") | O19: =IF(OR(M19="",N19=""),"",N19-M19) | P19: =IF(O19="","",IF(SIGN(ROUND(O19,6))=SIGN(ROUND(K19,6)),1,0)) | Q19: =IF(OR(G19<>"Y",O19=""),"",IF(SIGN(ROUND(O19,6))=SIGN(ROUND(H19-I19,6)),1,0)) | R19: =IF(G19<>"Y","",IF(SIGN(ROUND(K19,6))=SIGN(ROUND(H19-I19,6)),1,0)) -> 1
A20: 19 | B20: 4 | C20: HE-f3e48b301237 | D20: The Private Life of Sherlock Holmes | E20: Character Interaction | F20: 4 | I20: 0.3 | J20: 0.4 | K20: =J20-I20 -> 0.1 | L20: =VLOOKUP(TEXT(B20,"00"),'Blinding key'!$A$2:$G$26,7,FALSE()) -> B | M20: =IFERROR(AVERAGE(INDEX('R1'!$D$3:$M$27,$B20,IF($L20="A",$F20,$F20+5)),INDEX('R2'!$D$3:$M$27,$B20,IF($L20="A",$F20,$F20+5)),INDEX('R3'!$D$3:$M$27,$B20,IF($L20="A",$F20,$F20+5))),"") | N20: =IFERROR(AVERAGE(INDEX('R1'!$D$3:$M$27,$B20,IF($L20="A",$F20+5,$F20)),INDEX('R2'!$D$3:$M$27,$B20,IF($L20="A",$F20+5,$F20)),INDEX('R3'!$D$3:$M$27,$B20,IF($L20="A",$F20+5,$F20))),"") | O20: =IF(OR(M20="",N20=""),"",N20-M20) | P20: =IF(O20="","",IF(SIGN(ROUND(O20,6))=SIGN(ROUND(K20,6)),1,0)) | Q20: =IF(OR(G20<>"Y",O20=""),"",IF(SIGN(ROUND(O20,6))=SIGN(ROUND(H20-I20,6)),1,0)) | R20: =IF(G20<>"Y","",IF(SIGN(ROUND(K20,6))=SIGN(ROUND(H20-I20,6)),1,0))
A21: 20 | B21: 4 | C21: HE-f3e48b301237 | D21: The Private Life of Sherlock Holmes | E21: Emotion Intensity | F21: 5 | I21: 0.1 | J21: 0.5 | K21: =J21-I21 -> 0.4 | L21: =VLOOKUP(TEXT(B21,"00"),'Blinding key'!$A$2:$G$26,7,FALSE()) -> B | M21: =IFERROR(AVERAGE(INDEX('R1'!$D$3:$M$27,$B21,IF($L21="A",$F21,$F21+5)),INDEX('R2'!$D$3:$M$27,$B21,IF($L21="A",$F21,$F21+5)),INDEX('R3'!$D$3:$M$27,$B21,IF($L21="A",$F21,$F21+5))),"") | N21: =IFERROR(AVERAGE(INDEX('R1'!$D$3:$M$27,$B21,IF($L21="A",$F21+5,$F21)),INDEX('R2'!$D$3:$M$27,$B21,IF($L21="A",$F21+5,$F21)),INDEX('R3'!$D$3:$M$27,$B21,IF($L21="A",$F21+5,$F21))),"") | O21: =IF(OR(M21="",N21=""),"",N21-M21) | P21: =IF(O21="","",IF(SIGN(ROUND(O21,6))=SIGN(ROUND(K21,6)),1,0)) | Q21: =IF(OR(G21<>"Y",O21=""),"",IF(SIGN(ROUND(O21,6))=SIGN(ROUND(H21-I21,6)),1,0)) | R21: =IF(G21<>"Y","",IF(SIGN(ROUND(K21,6))=SIGN(ROUND(H21-I21,6)),1,0))
A22: 21 | B22: 5 | C22: HE-9b53a614098d | D22: The Private Life of Sherlock Holmes | E22: Pacing | F22: 1 | I22: 0.3 | J22: 0.7 | K22: =J22-I22 -> 0.4 | L22: =VLOOKUP(TEXT(B22,"00"),'Blinding key'!$A$2:$G$26,7,FALSE()) -> B | M22: =IFERROR(AVERAGE(INDEX('R1'!$D$3:$M$27,$B22,IF($L22="A",$F22,$F22+5)),INDEX('R2'!$D$3:$M$27,$B22,IF($L22="A",$F22,$F22+5)),INDEX('R3'!$D$3:$M$27,$B22,IF($L22="A",$F22,$F22+5))),"") | N22: =IFERROR(AVERAGE(INDEX('R1'!$D$3:$M$27,$B22,IF($L22="A",$F22+5,$F22)),INDEX('R2'!$D$3:$M$27,$B22,IF($L22="A",$F22+5,$F22)),INDEX('R3'!$D$3:$M$27,$B22,IF($L22="A",$F22+5,$F22))),"") | O22: =IF(OR(M22="",N22=""),"",N22-M22) | P22: =IF(O22="","",IF(SIGN(ROUND(O22,6))=SIGN(ROUND(K22,6)),1,0)) | Q22: =IF(OR(G22<>"Y",O22=""),"",IF(SIGN(ROUND(O22,6))=SIGN(ROUND(H22-I22,6)),1,0)) | R22: =IF(G22<>"Y","",IF(SIGN(ROUND(K22,6))=SIGN(ROUND(H22-I22,6)),1,0))
A23: 22 | B23: 5 | C23: HE-9b53a614098d | D23: The Private Life of Sherlock Holmes | E23: Dialogue Density | F23: 2 | I23: 0 | J23: 0.1 | K23: =J23-I23 -> 0.1 | L23: =VLOOKUP(TEXT(B23,"00"),'Blinding key'!$A$2:$G$26,7,FALSE()) -> B | M23: =IFERROR(AVERAGE(INDEX('R1'!$D$3:$M$27,$B23,IF($L23="A",$F23,$F23+5)),INDEX('R2'!$D$3:$M$27,$B23,IF($L23="A",$F23,$F23+5)),INDEX('R3'!$D$3:$M$27,$B23,IF($L23="A",$F23,$F23+5))),"") | N23: =IFERROR(AVERAGE(INDEX('R1'!$D$3:$M$27,$B23,IF($L23="A",$F23+5,$F23)),INDEX('R2'!$D$3:$M$27,$B23,IF($L23="A",$F23+5,$F23)),INDEX('R3'!$D$3:$M$27,$B23,IF($L23="A",$F23+5,$F23))),"") | O23: =IF(OR(M23="",N23=""),"",N23-M23) | P23: =IF(O23="","",IF(SIGN(ROUND(O23,6))=SIGN(ROUND(K23,6)),1,0)) | Q23: =IF(OR(G23<>"Y",O23=""),"",IF(SIGN(ROUND(O23,6))=SIGN(ROUND(H23-I23,6)),1,0)) | R23: =IF(G23<>"Y","",IF(SIGN(ROUND(K23,6))=SIGN(ROUND(H23-I23,6)),1,0))
A24: 23 | B24: 5 | C24: HE-9b53a614098d | D24: The Private Life of Sherlock Holmes | E24: Action Density | F24: 3 | G24: Y | H24: 0.9 | I24: 0.1 | J24: 0.8 | K24: =J24-I24 -> 0.7 | L24: =VLOOKUP(TEXT(B24,"00"),'Blinding key'!$A$2:$G$26,7,FALSE()) -> B | M24: =IFERROR(AVERAGE(INDEX('R1'!$D$3:$M$27,$B24,IF($L24="A",$F24,$F24+5)),INDEX('R2'!$D$3:$M$27,$B24,IF($L24="A",$F24,$F24+5)),INDEX('R3'!$D$3:$M$27,$B24,IF($L24="A",$F24,$F24+5))),"") | N24: =IFERROR(AVERAGE(INDEX('R1'!$D$3:$M$27,$B24,IF($L24="A",$F24+5,$F24)),INDEX('R2'!$D$3:$M$27,$B24,IF($L24="A",$F24+5,$F24)),INDEX('R3'!$D$3:$M$27,$B24,IF($L24="A",$F24+5,$F24))),"") | O24: =IF(OR(M24="",N24=""),"",N24-M24) | P24: =IF(O24="","",IF(SIGN(ROUND(O24,6))=SIGN(ROUND(K24,6)),1,0)) | Q24: =IF(OR(G24<>"Y",O24=""),"",IF(SIGN(ROUND(O24,6))=SIGN(ROUND(H24-I24,6)),1,0)) | R24: =IF(G24<>"Y","",IF(SIGN(ROUND(K24,6))=SIGN(ROUND(H24-I24,6)),1,0)) -> 1
A25: 24 | B25: 5 | C25: HE-9b53a614098d | D25: The Private Life of Sherlock Holmes | E25: Character Interaction | F25: 4 | I25: 0 | J25: 0.3 | K25: =J25-I25 -> 0.3 | L25: =VLOOKUP(TEXT(B25,"00"),'Blinding key'!$A$2:$G$26,7,FALSE()) -> B | M25: =IFERROR(AVERAGE(INDEX('R1'!$D$3:$M$27,$B25,IF($L25="A",$F25,$F25+5)),INDEX('R2'!$D$3:$M$27,$B25,IF($L25="A",$F25,$F25+5)),INDEX('R3'!$D$3:$M$27,$B25,IF($L25="A",$F25,$F25+5))),"") | N25: =IFERROR(AVERAGE(INDEX('R1'!$D$3:$M$27,$B25,IF($L25="A",$F25+5,$F25)),INDEX('R2'!$D$3:$M$27,$B25,IF($L25="A",$F25+5,$F25)),INDEX('R3'!$D$3:$M$27,$B25,IF($L25="A",$F25+5,$F25))),"") | O25: =IF(OR(M25="",N25=""),"",N25-M25) | P25: =IF(O25="","",IF(SIGN(ROUND(O25,6))=SIGN(ROUND(K25,6)),1,0)) | Q25: =IF(OR(G25<>"Y",O25=""),"",IF(SIGN(ROUND(O25,6))=SIGN(ROUND(H25-I25,6)),1,0)) | R25: =IF(G25<>"Y","",IF(SIGN(ROUND(K25,6))=SIGN(ROUND(H25-I25,6)),1,0))
A26: 25 | B26: 5 | C26: HE-9b53a614098d | D26: The Private Life of Sherlock Holmes | E26: Emotion Intensity | F26: 5 | I26: 0 | J26: 0.4 | K26: =J26-I26 -> 0.4 | L26: =VLOOKUP(TEXT(B26,"00"),'Blinding key'!$A$2:$G$26,7,FALSE()) -> B | M26: =IFERROR(AVERAGE(INDEX('R1'!$D$3:$M$27,$B26,IF($L26="A",$F26,$F26+5)),INDEX('R2'!$D$3:$M$27,$B26,IF($L26="A",$F26,$F26+5)),INDEX('R3'!$D$3:$M$27,$B26,IF($L26="A",$F26,$F26+5))),"") | N26: =IFERROR(AVERAGE(INDEX('R1'!$D$3:$M$27,$B26,IF($L26="A",$F26+5,$F26)),INDEX('R2'!$D$3:$M$27,$B26,IF($L26="A",$F26+5,$F26)),INDEX('R3'!$D$3:$M$27,$B26,IF($L26="A",$F26+5,$F26))),"") | O26: =IF(OR(M26="",N26=""),"",N26-M26) | P26: =IF(O26="","",IF(SIGN(ROUND(O26,6))=SIGN(ROUND(K26,6)),1,0)) | Q26: =IF(OR(G26<>"Y",O26=""),"",IF(SIGN(ROUND(O26,6))=SIGN(ROUND(H26-I26,6)),1,0)) | R26: =IF(G26<>"Y","",IF(SIGN(ROUND(K26,6))=SIGN(ROUND(H26-I26,6)),1,0))
A27: 26 | B27: 6 | C27: HE-02976e0045d3 | D27: Ghostbusters II | E27: Pacing | F27: 1 | I27: 0.6 | J27: 0.7 | K27: =J27-I27 -> 0.1 | L27: =VLOOKUP(TEXT(B27,"00"),'Blinding key'!$A$2:$G$26,7,FALSE()) -> A | M27: =IFERROR(AVERAGE(INDEX('R1'!$D$3:$M$27,$B27,IF($L27="A",$F27,$F27+5)),INDEX('R2'!$D$3:$M$27,$B27,IF($L27="A",$F27,$F27+5)),INDEX('R3'!$D$3:$M$27,$B27,IF($L27="A",$F27,$F27+5))),"") | N27: =IFERROR(AVERAGE(INDEX('R1'!$D$3:$M$27,$B27,IF($L27="A",$F27+5,$F27)),INDEX('R2'!$D$3:$M$27,$B27,IF($L27="A",$F27+5,$F27)),INDEX('R3'!$D$3:$M$27,$B27,IF($L27="A",$F27+5,$F27))),"") | O27: =IF(OR(M27="",N27=""),"",N27-M27) | P27: =IF(O27="","",IF(SIGN(ROUND(O27,6))=SIGN(ROUND(K27,6)),1,0)) | Q27: =IF(OR(G27<>"Y",O27=""),"",IF(SIGN(ROUND(O27,6))=SIGN(ROUND(H27-I27,6)),1,0)) | R27: =IF(G27<>"Y","",IF(SIGN(ROUND(K27,6))=SIGN(ROUND(H27-I27,6)),1,0))
A28: 27 | B28: 6 | C28: HE-02976e0045d3 | D28: Ghostbusters II | E28: Dialogue Density | F28: 2 | G28: Y | H28: 0.5 | I28: 0.4 | J28: 0.5 | K28: =J28-I28 -> 0.1 | L28: =VLOOKUP(TEXT(B28,"00"),'Blinding key'!$A$2:$G$26,7,FALSE()) -> A | M28: =IFERROR(AVERAGE(INDEX('R1'!$D$3:$M$27,$B28,IF($L28="A",$F28,$F28+5)),INDEX('R2'!$D$3:$M$27,$B28,IF($L28="A",$F28,$F28+5)),INDEX('R3'!$D$3:$M$27,$B28,IF($L28="A",$F28,$F28+5))),"") | N28: =IFERROR(AVERAGE(INDEX('R1'!$D$3:$M$27,$B28,IF($L28="A",$F28+5,$F28)),INDEX('R2'!$D$3:$M$27,$B28,IF($L28="A",$F28+5,$F28)),INDEX('R3'!$D$3:$M$27,$B28,IF($L28="A",$F28+5,$F28))),"") | O28: =IF(OR(M28="",N28=""),"",N28-M28) | P28: =IF(O28="","",IF(SIGN(ROUND(O28,6))=SIGN(ROUND(K28,6)),1,0)) | Q28: =IF(OR(G28<>"Y",O28=""),"",IF(SIGN(ROUND(O28,6))=SIGN(ROUND(H28-I28,6)),1,0)) | R28: =IF(G28<>"Y","",IF(SIGN(ROUND(K28,6))=SIGN(ROUND(H28-I28,6)),1,0)) -> 1
A29: 28 | B29: 6 | C29: HE-02976e0045d3 | D29: Ghostbusters II | E29: Action Density | F29: 3 | I29: 0.8 | J29: 0.8 | K29: =J29-I29 -> 0 | L29: =VLOOKUP(TEXT(B29,"00"),'Blinding key'!$A$2:$G$26,7,FALSE()) -> A | M29: =IFERROR(AVERAGE(INDEX('R1'!$D$3:$M$27,$B29,IF($L29="A",$F29,$F29+5)),INDEX('R2'!$D$3:$M$27,$B29,IF($L29="A",$F29,$F29+5)),INDEX('R3'!$D$3:$M$27,$B29,IF($L29="A",$F29,$F29+5))),"") | N29: =IFERROR(AVERAGE(INDEX('R1'!$D$3:$M$27,$B29,IF($L29="A",$F29+5,$F29)),INDEX('R2'!$D$3:$M$27,$B29,IF($L29="A",$F29+5,$F29)),INDEX('R3'!$D$3:$M$27,$B29,IF($L29="A",$F29+5,$F29))),"") | O29: =IF(OR(M29="",N29=""),"",N29-M29) | P29: =IF(O29="","",IF(SIGN(ROUND(O29,6))=SIGN(ROUND(K29,6)),1,0)) | Q29: =IF(OR(G29<>"Y",O29=""),"",IF(SIGN(ROUND(O29,6))=SIGN(ROUND(H29-I29,6)),1,0)) | R29: =IF(G29<>"Y","",IF(SIGN(ROUND(K29,6))=SIGN(ROUND(H29-I29,6)),1,0))
A30: 29 | B30: 6 | C30: HE-02976e0045d3 | D30: Ghostbusters II | E30: Character Interaction | F30: 4 | I30: 0.2 | J30: 0.3 | K30: =J30-I30 -> 0.1 | L30: =VLOOKUP(TEXT(B30,"00"),'Blinding key'!$A$2:$G$26,7,FALSE()) -> A | M30: =IFERROR(AVERAGE(INDEX('R1'!$D$3:$M$27,$B30,IF($L30="A",$F30,$F30+5)),INDEX('R2'!$D$3:$M$27,$B30,IF($L30="A",$F30,$F30+5)),INDEX('R3'!$D$3:$M$27,$B30,IF($L30="A",$F30,$F30+5))),"") | N30: =IFERROR(AVERAGE(INDEX('R1'!$D$3:$M$27,$B30,IF($L30="A",$F30+5,$F30)),INDEX('R2'!$D$3:$M$27,$B30,IF($L30="A",$F30+5,$F30)),INDEX('R3'!$D$3:$M$27,$B30,IF($L30="A",$F30+5,$F30))),"") | O30: =IF(OR(M30="",N30=""),"",N30-M30) | P30: =IF(O30="","",IF(SIGN(ROUND(O30,6))=SIGN(ROUND(K30,6)),1,0)) | Q30: =IF(OR(G30<>"Y",O30=""),"",IF(SIGN(ROUND(O30,6))=SIGN(ROUND(H30-I30,6)),1,0)) | R30: =IF(G30<>"Y","",IF(SIGN(ROUND(K30,6))=SIGN(ROUND(H30-I30,6)),1,0))
A31: 30 | B31: 6 | C31: HE-02976e0045d3 | D31: Ghostbusters II | E31: Emotion Intensity | F31: 5 | I31: 0.5 | J31: 0.6 | K31: =J31-I31 -> 0.1 | L31: =VLOOKUP(TEXT(B31,"00"),'Blinding key'!$A$2:$G$26,7,FALSE()) -> A | M31: =IFERROR(AVERAGE(INDEX('R1'!$D$3:$M$27,$B31,IF($L31="A",$F31,$F31+5)),INDEX('R2'!$D$3:$M$27,$B31,IF($L31="A",$F31,$F31+5)),INDEX('R3'!$D$3:$M$27,$B31,IF($L31="A",$F31,$F31+5))),"") | N31: =IFERROR(AVERAGE(INDEX('R1'!$D$3:$M$27,$B31,IF($L31="A",$F31+5,$F31)),INDEX('R2'!$D$3:$M$27,$B31,IF($L31="A",$F31+5,$F31)),INDEX('R3'!$D$3:$M$27,$B31,IF($L31="A",$F31+5,$F31))),"") | O31: =IF(OR(M31="",N31=""),"",N31-M31) | P31: =IF(O31="","",IF(SIGN(ROUND(O31,6))=SIGN(ROUND(K31,6)),1,0)) | Q31: =IF(OR(G31<>"Y",O31=""),"",IF(SIGN(ROUND(O31,6))=SIGN(ROUND(H31-I31,6)),1,0)) | R31: =IF(G31<>"Y","",IF(SIGN(ROUND(K31,6))=SIGN(ROUND(H31-I31,6)),1,0))
A32: 31 | B32: 7 | C32: HE-774e675404e7 | D32: Ghostbusters II | E32: Pacing | F32: 1 | I32: 0.3 | J32: 0.7 | K32: =J32-I32 -> 0.4 | L32: =VLOOKUP(TEXT(B32,"00"),'Blinding key'!$A$2:$G$26,7,FALSE()) -> A | M32: =IFERROR(AVERAGE(INDEX('R1'!$D$3:$M$27,$B32,IF($L32="A",$F32,$F32+5)),INDEX('R2'!$D$3:$M$27,$B32,IF($L32="A",$F32,$F32+5)),INDEX('R3'!$D$3:$M$27,$B32,IF($L32="A",$F32,$F32+5))),"") | N32: =IFERROR(AVERAGE(INDEX('R1'!$D$3:$M$27,$B32,IF($L32="A",$F32+5,$F32)),INDEX('R2'!$D$3:$M$27,$B32,IF($L32="A",$F32+5,$F32)),INDEX('R3'!$D$3:$M$27,$B32,IF($L32="A",$F32+5,$F32))),"") | O32: =IF(OR(M32="",N32=""),"",N32-M32) | P32: =IF(O32="","",IF(SIGN(ROUND(O32,6))=SIGN(ROUND(K32,6)),1,0)) | Q32: =IF(OR(G32<>"Y",O32=""),"",IF(SIGN(ROUND(O32,6))=SIGN(ROUND(H32-I32,6)),1,0)) | R32: =IF(G32<>"Y","",IF(SIGN(ROUND(K32,6))=SIGN(ROUND(H32-I32,6)),1,0))
A33: 32 | B33: 7 | C33: HE-774e675404e7 | D33: Ghostbusters II | E33: Dialogue Density | F33: 2 | G33: Y | H33: 0.5 | I33: 0.1 | J33: 0.4 | K33: =J33-I33 -> 0.3 | L33: =VLOOKUP(TEXT(B33,"00"),'Blinding key'!$A$2:$G$26,7,FALSE()) -> A | M33: =IFERROR(AVERAGE(INDEX('R1'!$D$3:$M$27,$B33,IF($L33="A",$F33,$F33+5)),INDEX('R2'!$D$3:$M$27,$B33,IF($L33="A",$F33,$F33+5)),INDEX('R3'!$D$3:$M$27,$B33,IF($L33="A",$F33,$F33+5))),"") | N33: =IFERROR(AVERAGE(INDEX('R1'!$D$3:$M$27,$B33,IF($L33="A",$F33+5,$F33)),INDEX('R2'!$D$3:$M$27,$B33,IF($L33="A",$F33+5,$F33)),INDEX('R3'!$D$3:$M$27,$B33,IF($L33="A",$F33+5,$F33))),"") | O33: =IF(OR(M33="",N33=""),"",N33-M33) | P33: =IF(O33="","",IF(SIGN(ROUND(O33,6))=SIGN(ROUND(K33,6)),1,0)) | Q33: =IF(OR(G33<>"Y",O33=""),"",IF(SIGN(ROUND(O33,6))=SIGN(ROUND(H33-I33,6)),1,0)) | R33: =IF(G33<>"Y","",IF(SIGN(ROUND(K33,6))=SIGN(ROUND(H33-I33,6)),1,0)) -> 1
A34: 33 | B34: 7 | C34: HE-774e675404e7 | D34: Ghostbusters II | E34: Action Density | F34: 3 | I34: 0.2 | J34: 0.3 | K34: =J34-I34 -> 0.1 | L34: =VLOOKUP(TEXT(B34,"00"),'Blinding key'!$A$2:$G$26,7,FALSE()) -> A | M34: =IFERROR(AVERAGE(INDEX('R1'!$D$3:$M$27,$B34,IF($L34="A",$F34,$F34+5)),INDEX('R2'!$D$3:$M$27,$B34,IF($L34="A",$F34,$F34+5)),INDEX('R3'!$D$3:$M$27,$B34,IF($L34="A",$F34,$F34+5))),"") | N34: =IFERROR(AVERAGE(INDEX('R1'!$D$3:$M$27,$B34,IF($L34="A",$F34+5,$F34)),INDEX('R2'!$D$3:$M$27,$B34,IF($L34="A",$F34+5,$F34)),INDEX('R3'!$D$3:$M$27,$B34,IF($L34="A",$F34+5,$F34))),"") | O34: =IF(OR(M34="",N34=""),"",N34-M34) | P34: =IF(O34="","",IF(SIGN(ROUND(O34,6))=SIGN(ROUND(K34,6)),1,0)) | Q34: =IF(OR(G34<>"Y",O34=""),"",IF(SIGN(ROUND(O34,6))=SIGN(ROUND(H34-I34,6)),1,0)) | R34: =IF(G34<>"Y","",IF(SIGN(ROUND(K34,6))=SIGN(ROUND(H34-I34,6)),1,0))
A35: 34 | B35: 7 | C35: HE-774e675404e7 | D35: Ghostbusters II | E35: Character Interaction | F35: 4 | I35: 0.1 | J35: 0.6 | K35: =J35-I35 -> 0.5 | L35: =VLOOKUP(TEXT(B35,"00"),'Blinding key'!$A$2:$G$26,7,FALSE()) -> A | M35: =IFERROR(AVERAGE(INDEX('R1'!$D$3:$M$27,$B35,IF($L35="A",$F35,$F35+5)),INDEX('R2'!$D$3:$M$27,$B35,IF($L35="A",$F35,$F35+5)),INDEX('R3'!$D$3:$M$27,$B35,IF($L35="A",$F35,$F35+5))),"") | N35: =IFERROR(AVERAGE(INDEX('R1'!$D$3:$M$27,$B35,IF($L35="A",$F35+5,$F35)),INDEX('R2'!$D$3:$M$27,$B35,IF($L35="A",$F35+5,$F35)),INDEX('R3'!$D$3:$M$27,$B35,IF($L35="A",$F35+5,$F35))),"") | O35: =IF(OR(M35="",N35=""),"",N35-M35) | P35: =IF(O35="","",IF(SIGN(ROUND(O35,6))=SIGN(ROUND(K35,6)),1,0)) | Q35: =IF(OR(G35<>"Y",O35=""),"",IF(SIGN(ROUND(O35,6))=SIGN(ROUND(H35-I35,6)),1,0)) | R35: =IF(G35<>"Y","",IF(SIGN(ROUND(K35,6))=SIGN(ROUND(H35-I35,6)),1,0))
A36: 35 | B36: 7 | C36: HE-774e675404e7 | D36: Ghostbusters II | E36: Emotion Intensity | F36: 5 | I36: 0.7 | J36: 0.5 | K36: =J36-I36 -> -0.2 | L36: =VLOOKUP(TEXT(B36,"00"),'Blinding key'!$A$2:$G$26,7,FALSE()) -> A | M36: =IFERROR(AVERAGE(INDEX('R1'!$D$3:$M$27,$B36,IF($L36="A",$F36,$F36+5)),INDEX('R2'!$D$3:$M$27,$B36,IF($L36="A",$F36,$F36+5)),INDEX('R3'!$D$3:$M$27,$B36,IF($L36="A",$F36,$F36+5))),"") | N36: =IFERROR(AVERAGE(INDEX('R1'!$D$3:$M$27,$B36,IF($L36="A",$F36+5,$F36)),INDEX('R2'!$D$3:$M$27,$B36,IF($L36="A",$F36+5,$F36)),INDEX('R3'!$D$3:$M$27,$B36,IF($L36="A",$F36+5,$F36))),"") | O36: =IF(OR(M36="",N36=""),"",N36-M36) | P36: =IF(O36="","",IF(SIGN(ROUND(O36,6))=SIGN(ROUND(K36,6)),1,0)) | Q36: =IF(OR(G36<>"Y",O36=""),"",IF(SIGN(ROUND(O36,6))=SIGN(ROUND(H36-I36,6)),1,0)) | R36: =IF(G36<>"Y","",IF(SIGN(ROUND(K36,6))=SIGN(ROUND(H36-I36,6)),1,0))
A37: 36 | B37: 8 | C37: HE-14dd09a43c06 | D37: Dog Day Afternoon | E37: Pacing | F37: 1 | I37: 0.6 | J37: 0.7 | K37: =J37-I37 -> 0.1 | L37: =VLOOKUP(TEXT(B37,"00"),'Blinding key'!$A$2:$G$26,7,FALSE()) -> A | M37: =IFERROR(AVERAGE(INDEX('R1'!$D$3:$M$27,$B37,IF($L37="A",$F37,$F37+5)),INDEX('R2'!$D$3:$M$27,$B37,IF($L37="A",$F37,$F37+5)),INDEX('R3'!$D$3:$M$27,$B37,IF($L37="A",$F37,$F37+5))),"") | N37: =IFERROR(AVERAGE(INDEX('R1'!$D$3:$M$27,$B37,IF($L37="A",$F37+5,$F37)),INDEX('R2'!$D$3:$M$27,$B37,IF($L37="A",$F37+5,$F37)),INDEX('R3'!$D$3:$M$27,$B37,IF($L37="A",$F37+5,$F37))),"") | O37: =IF(OR(M37="",N37=""),"",N37-M37) | P37: =IF(O37="","",IF(SIGN(ROUND(O37,6))=SIGN(ROUND(K37,6)),1,0)) | Q37: =IF(OR(G37<>"Y",O37=""),"",IF(SIGN(ROUND(O37,6))=SIGN(ROUND(H37-I37,6)),1,0)) | R37: =IF(G37<>"Y","",IF(SIGN(ROUND(K37,6))=SIGN(ROUND(H37-I37,6)),1,0))
A38: 37 | B38: 8 | C38: HE-14dd09a43c06 | D38: Dog Day Afternoon | E38: Dialogue Density | F38: 2 | I38: 0.8 | J38: 0.5 | K38: =J38-I38 -> -0.3 | L38: =VLOOKUP(TEXT(B38,"00"),'Blinding key'!$A$2:$G$26,7,FALSE()) -> A | M38: =IFERROR(AVERAGE(INDEX('R1'!$D$3:$M$27,$B38,IF($L38="A",$F38,$F38+5)),INDEX('R2'!$D$3:$M$27,$B38,IF($L38="A",$F38,$F38+5)),INDEX('R3'!$D$3:$M$27,$B38,IF($L38="A",$F38,$F38+5))),"") | N38: =IFERROR(AVERAGE(INDEX('R1'!$D$3:$M$27,$B38,IF($L38="A",$F38+5,$F38)),INDEX('R2'!$D$3:$M$27,$B38,IF($L38="A",$F38+5,$F38)),INDEX('R3'!$D$3:$M$27,$B38,IF($L38="A",$F38+5,$F38))),"") | O38: =IF(OR(M38="",N38=""),"",N38-M38) | P38: =IF(O38="","",IF(SIGN(ROUND(O38,6))=SIGN(ROUND(K38,6)),1,0)) | Q38: =IF(OR(G38<>"Y",O38=""),"",IF(SIGN(ROUND(O38,6))=SIGN(ROUND(H38-I38,6)),1,0)) | R38: =IF(G38<>"Y","",IF(SIGN(ROUND(K38,6))=SIGN(ROUND(H38-I38,6)),1,0))
A39: 38 | B39: 8 | C39: HE-14dd09a43c06 | D39: Dog Day Afternoon | E39: Action Density | F39: 3 | I39: 0.4 | J39: 0.3 | K39: =J39-I39 -> -0.1 | L39: =VLOOKUP(TEXT(B39,"00"),'Blinding key'!$A$2:$G$26,7,FALSE()) -> A | M39: =IFERROR(AVERAGE(INDEX('R1'!$D$3:$M$27,$B39,IF($L39="A",$F39,$F39+5)),INDEX('R2'!$D$3:$M$27,$B39,IF($L39="A",$F39,$F39+5)),INDEX('R3'!$D$3:$M$27,$B39,IF($L39="A",$F39,$F39+5))),"") | N39: =IFERROR(AVERAGE(INDEX('R1'!$D$3:$M$27,$B39,IF($L39="A",$F39+5,$F39)),INDEX('R2'!$D$3:$M$27,$B39,IF($L39="A",$F39+5,$F39)),INDEX('R3'!$D$3:$M$27,$B39,IF($L39="A",$F39+5,$F39))),"") | O39: =IF(OR(M39="",N39=""),"",N39-M39) | P39: =IF(O39="","",IF(SIGN(ROUND(O39,6))=SIGN(ROUND(K39,6)),1,0)) | Q39: =IF(OR(G39<>"Y",O39=""),"",IF(SIGN(ROUND(O39,6))=SIGN(ROUND(H39-I39,6)),1,0)) | R39: =IF(G39<>"Y","",IF(SIGN(ROUND(K39,6))=SIGN(ROUND(H39-I39,6)),1,0))
A40: 39 | B40: 8 | C40: HE-14dd09a43c06 | D40: Dog Day Afternoon | E40: Character Interaction | F40: 4 | G40: Y | H40: 0.8 | I40: 0.7 | J40: 0.6 | K40: =J40-I40 -> -0.1 | L40: =VLOOKUP(TEXT(B40,"00"),'Blinding key'!$A$2:$G$26,7,FALSE()) -> A | M40: =IFERROR(AVERAGE(INDEX('R1'!$D$3:$M$27,$B40,IF($L40="A",$F40,$F40+5)),INDEX('R2'!$D$3:$M$27,$B40,IF($L40="A",$F40,$F40+5)),INDEX('R3'!$D$3:$M$27,$B40,IF($L40="A",$F40,$F40+5))),"") | N40: =IFERROR(AVERAGE(INDEX('R1'!$D$3:$M$27,$B40,IF($L40="A",$F40+5,$F40)),INDEX('R2'!$D$3:$M$27,$B40,IF($L40="A",$F40+5,$F40)),INDEX('R3'!$D$3:$M$27,$B40,IF($L40="A",$F40+5,$F40))),"") | O40: =IF(OR(M40="",N40=""),"",N40-M40) | P40: =IF(O40="","",IF(SIGN(ROUND(O40,6))=SIGN(ROUND(K40,6)),1,0)) | Q40: =IF(OR(G40<>"Y",O40=""),"",IF(SIGN(ROUND(O40,6))=SIGN(ROUND(H40-I40,6)),1,0)) | R40: =IF(G40<>"Y","",IF(SIGN(ROUND(K40,6))=SIGN(ROUND(H40-I40,6)),1,0)) -> 0
...

Sheet Quality
A1: Pair | B1: Original shown as | C1: Coherence Original | D1: Coherence Rewrite | E1: Coherence Rew − Orig | F1: Acceptability Original | G1: Acceptability Rewrite | H1: Acceptability Rew − Orig | I1: Characters: # Different | J1: Setting: # Different | K1: Events: # Different | L1: Content changed (≥2 raters, 1/0)
A2: 01 | B2: =VLOOKUP(A2,'Blinding key'!$A$2:$G$26,7,FALSE()) -> B | C2: =IFERROR(AVERAGE(INDEX('R1'!$D$3:$U$27,1,IF($B2="A",14,15)),INDEX('R2'!$D$3:$U$27,1,IF($B2="A",14,15)),INDEX('R3'!$D$3:$U$27,1,IF($B2="A",14,15))),"") | D2: =IFERROR(AVERAGE(INDEX('R1'!$D$3:$U$27,1,IF($B2="A",15,14)),INDEX('R2'!$D$3:$U$27,1,IF($B2="A",15,14)),INDEX('R3'!$D$3:$U$27,1,IF($B2="A",15,14))),"") | E2: =IF(OR(C2="",D2=""),"",D2-C2) | F2: =IFERROR(AVERAGE(INDEX('R1'!$D$3:$U$27,1,IF($B2="A",16,17)),INDEX('R2'!$D$3:$U$27,1,IF($B2="A",16,17)),INDEX('R3'!$D$3:$U$27,1,IF($B2="A",16,17))),"") | G2: =IFERROR(AVERAGE(INDEX('R1'!$D$3:$U$27,1,IF($B2="A",17,16)),INDEX('R2'!$D$3:$U$27,1,IF($B2="A",17,16)),INDEX('R3'!$D$3:$U$27,1,IF($B2="A",17,16))),"") | H2: =IF(OR(F2="",G2=""),"",G2-F2) | I2: =(INDEX('R1'!$D$3:$U$27,1,11)="Different")+(INDEX('R2'!$D$3:$U$27,1,11)="Different")+(INDEX('R3'!$D$3:$U$27,1,11)="Different") -> 0 | J2: =(INDEX('R1'!$D$3:$U$27,1,12)="Different")+(INDEX('R2'!$D$3:$U$27,1,12)="Different")+(INDEX('R3'!$D$3:$U$27,1,12)="Different") -> 0 | K2: =(INDEX('R1'!$D$3:$U$27,1,13)="Different")+(INDEX('R2'!$D$3:$U$27,1,13)="Different")+(INDEX('R3'!$D$3:$U$27,1,13)="Different") -> 0 | L2: =IF(C2="","",IF(OR(I2>=2,J2>=2,K2>=2),1,0))
A3: 02 | B3: =VLOOKUP(A3,'Blinding key'!$A$2:$G$26,7,FALSE()) -> A | C3: =IFERROR(AVERAGE(INDEX('R1'!$D$3:$U$27,2,IF($B3="A",14,15)),INDEX('R2'!$D$3:$U$27,2,IF($B3="A",14,15)),INDEX('R3'!$D$3:$U$27,2,IF($B3="A",14,15))),"") | D3: =IFERROR(AVERAGE(INDEX('R1'!$D$3:$U$27,2,IF($B3="A",15,14)),INDEX('R2'!$D$3:$U$27,2,IF($B3="A",15,14)),INDEX('R3'!$D$3:$U$27,2,IF($B3="A",15,14))),"") | E3: =IF(OR(C3="",D3=""),"",D3-C3) | F3: =IFERROR(AVERAGE(INDEX('R1'!$D$3:$U$27,2,IF($B3="A",16,17)),INDEX('R2'!$D$3:$U$27,2,IF($B3="A",16,17)),INDEX('R3'!$D$3:$U$27,2,IF($B3="A",16,17))),"") | G3: =IFERROR(AVERAGE(INDEX('R1'!$D$3:$U$27,2,IF($B3="A",17,16)),INDEX('R2'!$D$3:$U$27,2,IF($B3="A",17,16)),INDEX('R3'!$D$3:$U$27,2,IF($B3="A",17,16))),"") | H3: =IF(OR(F3="",G3=""),"",G3-F3) | I3: =(INDEX('R1'!$D$3:$U$27,2,11)="Different")+(INDEX('R2'!$D$3:$U$27,2,11)="Different")+(INDEX('R3'!$D$3:$U$27,2,11)="Different") -> 0 | J3: =(INDEX('R1'!$D$3:$U$27,2,12)="Different")+(INDEX('R2'!$D$3:$U$27,2,12)="Different")+(INDEX('R3'!$D$3:$U$27,2,12)="Different") -> 0 | K3: =(INDEX('R1'!$D$3:$U$27,2,13)="Different")+(INDEX('R2'!$D$3:$U$27,2,13)="Different")+(INDEX('R3'!$D$3:$U$27,2,13)="Different") -> 0 | L3: =IF(C3="","",IF(OR(I3>=2,J3>=2,K3>=2),1,0))
A4: 03 | B4: =VLOOKUP(A4,'Blinding key'!$A$2:$G$26,7,FALSE()) -> A | C4: =IFERROR(AVERAGE(INDEX('R1'!$D$3:$U$27,3,IF($B4="A",14,15)),INDEX('R2'!$D$3:$U$27,3,IF($B4="A",14,15)),INDEX('R3'!$D$3:$U$27,3,IF($B4="A",14,15))),"") | D4: =IFERROR(AVERAGE(INDEX('R1'!$D$3:$U$27,3,IF($B4="A",15,14)),INDEX('R2'!$D$3:$U$27,3,IF($B4="A",15,14)),INDEX('R3'!$D$3:$U$27,3,IF($B4="A",15,14))),"") | E4: =IF(OR(C4="",D4=""),"",D4-C4) | F4: =IFERROR(AVERAGE(INDEX('R1'!$D$3:$U$27,3,IF($B4="A",16,17)),INDEX('R2'!$D$3:$U$27,3,IF($B4="A",16,17)),INDEX('R3'!$D$3:$U$27,3,IF($B4="A",16,17))),"") | G4: =IFERROR(AVERAGE(INDEX('R1'!$D$3:$U$27,3,IF($B4="A",17,16)),INDEX('R2'!$D$3:$U$27,3,IF($B4="A",17,16)),INDEX('R3'!$D$3:$U$27,3,IF($B4="A",17,16))),"") | H4: =IF(OR(F4="",G4=""),"",G4-F4) | I4: =(INDEX('R1'!$D$3:$U$27,3,11)="Different")+(INDEX('R2'!$D$3:$U$27,3,11)="Different")+(INDEX('R3'!$D$3:$U$27,3,11)="Different") -> 0 | J4: =(INDEX('R1'!$D$3:$U$27,3,12)="Different")+(INDEX('R2'!$D$3:$U$27,3,12)="Different")+(INDEX('R3'!$D$3:$U$27,3,12)="Different") -> 0 | K4: =(INDEX('R1'!$D$3:$U$27,3,13)="Different")+(INDEX('R2'!$D$3:$U$27,3,13)="Different")+(INDEX('R3'!$D$3:$U$27,3,13)="Different") -> 0 | L4: =IF(C4="","",IF(OR(I4>=2,J4>=2,K4>=2),1,0))
A5: 04 | B5: =VLOOKUP(A5,'Blinding key'!$A$2:$G$26,7,FALSE()) -> B | C5: =IFERROR(AVERAGE(INDEX('R1'!$D$3:$U$27,4,IF($B5="A",14,15)),INDEX('R2'!$D$3:$U$27,4,IF($B5="A",14,15)),INDEX('R3'!$D$3:$U$27,4,IF($B5="A",14,15))),"") | D5: =IFERROR(AVERAGE(INDEX('R1'!$D$3:$U$27,4,IF($B5="A",15,14)),INDEX('R2'!$D$3:$U$27,4,IF($B5="A",15,14)),INDEX('R3'!$D$3:$U$27,4,IF($B5="A",15,14))),"") | E5: =IF(OR(C5="",D5=""),"",D5-C5) | F5: =IFERROR(AVERAGE(INDEX('R1'!$D$3:$U$27,4,IF($B5="A",16,17)),INDEX('R2'!$D$3:$U$27,4,IF($B5="A",16,17)),INDEX('R3'!$D$3:$U$27,4,IF($B5="A",16,17))),"") | G5: =IFERROR(AVERAGE(INDEX('R1'!$D$3:$U$27,4,IF($B5="A",17,16)),INDEX('R2'!$D$3:$U$27,4,IF($B5="A",17,16)),INDEX('R3'!$D$3:$U$27,4,IF($B5="A",17,16))),"") | H5: =IF(OR(F5="",G5=""),"",G5-F5) | I5: =(INDEX('R1'!$D$3:$U$27,4,11)="Different")+(INDEX('R2'!$D$3:$U$27,4,11)="Different")+(INDEX('R3'!$D$3:$U$27,4,11)="Different") -> 0 | J5: =(INDEX('R1'!$D$3:$U$27,4,12)="Different")+(INDEX('R2'!$D$3:$U$27,4,12)="Different")+(INDEX('R3'!$D$3:$U$27,4,12)="Different") -> 0 | K5: =(INDEX('R1'!$D$3:$U$27,4,13)="Different")+(INDEX('R2'!$D$3:$U$27,4,13)="Different")+(INDEX('R3'!$D$3:$U$27,4,13)="Different") -> 0 | L5: =IF(C5="","",IF(OR(I5>=2,J5>=2,K5>=2),1,0))
A6: 05 | B6: =VLOOKUP(A6,'Blinding key'!$A$2:$G$26,7,FALSE()) -> B | C6: =IFERROR(AVERAGE(INDEX('R1'!$D$3:$U$27,5,IF($B6="A",14,15)),INDEX('R2'!$D$3:$U$27,5,IF($B6="A",14,15)),INDEX('R3'!$D$3:$U$27,5,IF($B6="A",14,15))),"") | D6: =IFERROR(AVERAGE(INDEX('R1'!$D$3:$U$27,5,IF($B6="A",15,14)),INDEX('R2'!$D$3:$U$27,5,IF($B6="A",15,14)),INDEX('R3'!$D$3:$U$27,5,IF($B6="A",15,14))),"") | E6: =IF(OR(C6="",D6=""),"",D6-C6) | F6: =IFERROR(AVERAGE(INDEX('R1'!$D$3:$U$27,5,IF($B6="A",16,17)),INDEX('R2'!$D$3:$U$27,5,IF($B6="A",16,17)),INDEX('R3'!$D$3:$U$27,5,IF($B6="A",16,17))),"") | G6: =IFERROR(AVERAGE(INDEX('R1'!$D$3:$U$27,5,IF($B6="A",17,16)),INDEX('R2'!$D$3:$U$27,5,IF($B6="A",17,16)),INDEX('R3'!$D$3:$U$27,5,IF($B6="A",17,16))),"") | H6: =IF(OR(F6="",G6=""),"",G6-F6) | I6: =(INDEX('R1'!$D$3:$U$27,5,11)="Different")+(INDEX('R2'!$D$3:$U$27,5,11)="Different")+(INDEX('R3'!$D$3:$U$27,5,11)="Different") -> 0 | J6: =(INDEX('R1'!$D$3:$U$27,5,12)="Different")+(INDEX('R2'!$D$3:$U$27,5,12)="Different")+(INDEX('R3'!$D$3:$U$27,5,12)="Different") -> 0 | K6: =(INDEX('R1'!$D$3:$U$27,5,13)="Different")+(INDEX('R2'!$D$3:$U$27,5,13)="Different")+(INDEX('R3'!$D$3:$U$27,5,13)="Different") -> 0 | L6: =IF(C6="","",IF(OR(I6>=2,J6>=2,K6>=2),1,0))
A7: 06 | B7: =VLOOKUP(A7,'Blinding key'!$A$2:$G$26,7,FALSE()) -> A | C7: =IFERROR(AVERAGE(INDEX('R1'!$D$3:$U$27,6,IF($B7="A",14,15)),INDEX('R2'!$D$3:$U$27,6,IF($B7="A",14,15)),INDEX('R3'!$D$3:$U$27,6,IF($B7="A",14,15))),"") | D7: =IFERROR(AVERAGE(INDEX('R1'!$D$3:$U$27,6,IF($B7="A",15,14)),INDEX('R2'!$D$3:$U$27,6,IF($B7="A",15,14)),INDEX('R3'!$D$3:$U$27,6,IF($B7="A",15,14))),"") | E7: =IF(OR(C7="",D7=""),"",D7-C7) | F7: =IFERROR(AVERAGE(INDEX('R1'!$D$3:$U$27,6,IF($B7="A",16,17)),INDEX('R2'!$D$3:$U$27,6,IF($B7="A",16,17)),INDEX('R3'!$D$3:$U$27,6,IF($B7="A",16,17))),"") | G7: =IFERROR(AVERAGE(INDEX('R1'!$D$3:$U$27,6,IF($B7="A",17,16)),INDEX('R2'!$D$3:$U$27,6,IF($B7="A",17,16)),INDEX('R3'!$D$3:$U$27,6,IF($B7="A",17,16))),"") | H7: =IF(OR(F7="",G7=""),"",G7-F7) | I7: =(INDEX('R1'!$D$3:$U$27,6,11)="Different")+(INDEX('R2'!$D$3:$U$27,6,11)="Different")+(INDEX('R3'!$D$3:$U$27,6,11)="Different") -> 0 | J7: =(INDEX('R1'!$D$3:$U$27,6,12)="Different")+(INDEX('R2'!$D$3:$U$27,6,12)="Different")+(INDEX('R3'!$D$3:$U$27,6,12)="Different") -> 0 | K7: =(INDEX('R1'!$D$3:$U$27,6,13)="Different")+(INDEX('R2'!$D$3:$U$27,6,13)="Different")+(INDEX('R3'!$D$3:$U$27,6,13)="Different") -> 0 | L7: =IF(C7="","",IF(OR(I7>=2,J7>=2,K7>=2),1,0))
A8: 07 | B8: =VLOOKUP(A8,'Blinding key'!$A$2:$G$26,7,FALSE()) -> A | C8: =IFERROR(AVERAGE(INDEX('R1'!$D$3:$U$27,7,IF($B8="A",14,15)),INDEX('R2'!$D$3:$U$27,7,IF($B8="A",14,15)),INDEX('R3'!$D$3:$U$27,7,IF($B8="A",14,15))),"") | D8: =IFERROR(AVERAGE(INDEX('R1'!$D$3:$U$27,7,IF($B8="A",15,14)),INDEX('R2'!$D$3:$U$27,7,IF($B8="A",15,14)),INDEX('R3'!$D$3:$U$27,7,IF($B8="A",15,14))),"") | E8: =IF(OR(C8="",D8=""),"",D8-C8) | F8: =IFERROR(AVERAGE(INDEX('R1'!$D$3:$U$27,7,IF($B8="A",16,17)),INDEX('R2'!$D$3:$U$27,7,IF($B8="A",16,17)),INDEX('R3'!$D$3:$U$27,7,IF($B8="A",16,17))),"") | G8: =IFERROR(AVERAGE(INDEX('R1'!$D$3:$U$27,7,IF($B8="A",17,16)),INDEX('R2'!$D$3:$U$27,7,IF($B8="A",17,16)),INDEX('R3'!$D$3:$U$27,7,IF($B8="A",17,16))),"") | H8: =IF(OR(F8="",G8=""),"",G8-F8) | I8: =(INDEX('R1'!$D$3:$U$27,7,11)="Different")+(INDEX('R2'!$D$3:$U$27,7,11)="Different")+(INDEX('R3'!$D$3:$U$27,7,11)="Different") -> 0 | J8: =(INDEX('R1'!$D$3:$U$27,7,12)="Different")+(INDEX('R2'!$D$3:$U$27,7,12)="Different")+(INDEX('R3'!$D$3:$U$27,7,12)="Different") -> 0 | K8: =(INDEX('R1'!$D$3:$U$27,7,13)="Different")+(INDEX('R2'!$D$3:$U$27,7,13)="Different")+(INDEX('R3'!$D$3:$U$27,7,13)="Different") -> 0 | L8: =IF(C8="","",IF(OR(I8>=2,J8>=2,K8>=2),1,0))
A9: 08 | B9: =VLOOKUP(A9,'Blinding key'!$A$2:$G$26,7,FALSE()) -> A | C9: =IFERROR(AVERAGE(INDEX('R1'!$D$3:$U$27,8,IF($B9="A",14,15)),INDEX('R2'!$D$3:$U$27,8,IF($B9="A",14,15)),INDEX('R3'!$D$3:$U$27,8,IF($B9="A",14,15))),"") | D9: =IFERROR(AVERAGE(INDEX('R1'!$D$3:$U$27,8,IF($B9="A",15,14)),INDEX('R2'!$D$3:$U$27,8,IF($B9="A",15,14)),INDEX('R3'!$D$3:$U$27,8,IF($B9="A",15,14))),"") | E9: =IF(OR(C9="",D9=""),"",D9-C9) | F9: =IFERROR(AVERAGE(INDEX('R1'!$D$3:$U$27,8,IF($B9="A",16,17)),INDEX('R2'!$D$3:$U$27,8,IF($B9="A",16,17)),INDEX('R3'!$D$3:$U$27,8,IF($B9="A",16,17))),"") | G9: =IFERROR(AVERAGE(INDEX('R1'!$D$3:$U$27,8,IF($B9="A",17,16)),INDEX('R2'!$D$3:$U$27,8,IF($B9="A",17,16)),INDEX('R3'!$D$3:$U$27,8,IF($B9="A",17,16))),"") | H9: =IF(OR(F9="",G9=""),"",G9-F9) | I9: =(INDEX('R1'!$D$3:$U$27,8,11)="Different")+(INDEX('R2'!$D$3:$U$27,8,11)="Different")+(INDEX('R3'!$D$3:$U$27,8,11)="Different") -> 0 | J9: =(INDEX('R1'!$D$3:$U$27,8,12)="Different")+(INDEX('R2'!$D$3:$U$27,8,12)="Different")+(INDEX('R3'!$D$3:$U$27,8,12)="Different") -> 0 | K9: =(INDEX('R1'!$D$3:$U$27,8,13)="Different")+(INDEX('R2'!$D$3:$U$27,8,13)="Different")+(INDEX('R3'!$D$3:$U$27,8,13)="Different") -> 0 | L9: =IF(C9="","",IF(OR(I9>=2,J9>=2,K9>=2),1,0))
A10: 09 | B10: =VLOOKUP(A10,'Blinding key'!$A$2:$G$26,7,FALSE()) -> B | C10: =IFERROR(AVERAGE(INDEX('R1'!$D$3:$U$27,9,IF($B10="A",14,15)),INDEX('R2'!$D$3:$U$27,9,IF($B10="A",14,15)),INDEX('R3'!$D$3:$U$27,9,IF($B10="A",14,15))),"") | D10: =IFERROR(AVERAGE(INDEX('R1'!$D$3:$U$27,9,IF($B10="A",15,14)),INDEX('R2'!$D$3:$U$27,9,IF($B10="A",15,14)),INDEX('R3'!$D$3:$U$27,9,IF($B10="A",15,14))),"") | E10: =IF(OR(C10="",D10=""),"",D10-C10) | F10: =IFERROR(AVERAGE(INDEX('R1'!$D$3:$U$27,9,IF($B10="A",16,17)),INDEX('R2'!$D$3:$U$27,9,IF($B10="A",16,17)),INDEX('R3'!$D$3:$U$27,9,IF($B10="A",16,17))),"") | G10: =IFERROR(AVERAGE(INDEX('R1'!$D$3:$U$27,9,IF($B10="A",17,16)),INDEX('R2'!$D$3:$U$27,9,IF($B10="A",17,16)),INDEX('R3'!$D$3:$U$27,9,IF($B10="A",17,16))),"") | H10: =IF(OR(F10="",G10=""),"",G10-F10) | I10: =(INDEX('R1'!$D$3:$U$27,9,11)="Different")+(INDEX('R2'!$D$3:$U$27,9,11)="Different")+(INDEX('R3'!$D$3:$U$27,9,11)="Different") -> 0 | J10: =(INDEX('R1'!$D$3:$U$27,9,12)="Different")+(INDEX('R2'!$D$3:$U$27,9,12)="Different")+(INDEX('R3'!$D$3:$U$27,9,12)="Different") -> 0 | K10: =(INDEX('R1'!$D$3:$U$27,9,13)="Different")+(INDEX('R2'!$D$3:$U$27,9,13)="Different")+(INDEX('R3'!$D$3:$U$27,9,13)="Different") -> 0 | L10: =IF(C10="","",IF(OR(I10>=2,J10>=2,K10>=2),1,0))
A11: 10 | B11: =VLOOKUP(A11,'Blinding key'!$A$2:$G$26,7,FALSE()) -> B | C11: =IFERROR(AVERAGE(INDEX('R1'!$D$3:$U$27,10,IF($B11="A",14,15)),INDEX('R2'!$D$3:$U$27,10,IF($B11="A",14,15)),INDEX('R3'!$D$3:$U$27,10,IF($B11="A",14,15))),"") | D11: =IFERROR(AVERAGE(INDEX('R1'!$D$3:$U$27,10,IF($B11="A",15,14)),INDEX('R2'!$D$3:$U$27,10,IF($B11="A",15,14)),INDEX('R3'!$D$3:$U$27,10,IF($B11="A",15,14))),"") | E11: =IF(OR(C11="",D11=""),"",D11-C11) | F11: =IFERROR(AVERAGE(INDEX('R1'!$D$3:$U$27,10,IF($B11="A",16,17)),INDEX('R2'!$D$3:$U$27,10,IF($B11="A",16,17)),INDEX('R3'!$D$3:$U$27,10,IF($B11="A",16,17))),"") | G11: =IFERROR(AVERAGE(INDEX('R1'!$D$3:$U$27,10,IF($B11="A",17,16)),INDEX('R2'!$D$3:$U$27,10,IF($B11="A",17,16)),INDEX('R3'!$D$3:$U$27,10,IF($B11="A",17,16))),"") | H11: =IF(OR(F11="",G11=""),"",G11-F11) | I11: =(INDEX('R1'!$D$3:$U$27,10,11)="Different")+(INDEX('R2'!$D$3:$U$27,10,11)="Different")+(INDEX('R3'!$D$3:$U$27,10,11)="Different") -> 0 | J11: =(INDEX('R1'!$D$3:$U$27,10,12)="Different")+(INDEX('R2'!$D$3:$U$27,10,12)="Different")+(INDEX('R3'!$D$3:$U$27,10,12)="Different") -> 0 | K11: =(INDEX('R1'!$D$3:$U$27,10,13)="Different")+(INDEX('R2'!$D$3:$U$27,10,13)="Different")+(INDEX('R3'!$D$3:$U$27,10,13)="Different") -> 0 | L11: =IF(C11="","",IF(OR(I11>=2,J11>=2,K11>=2),1,0))
A12: 11 | B12: =VLOOKUP(A12,'Blinding key'!$A$2:$G$26,7,FALSE()) -> A | C12: =IFERROR(AVERAGE(INDEX('R1'!$D$3:$U$27,11,IF($B12="A",14,15)),INDEX('R2'!$D$3:$U$27,11,IF($B12="A",14,15)),INDEX('R3'!$D$3:$U$27,11,IF($B12="A",14,15))),"") | D12: =IFERROR(AVERAGE(INDEX('R1'!$D$3:$U$27,11,IF($B12="A",15,14)),INDEX('R2'!$D$3:$U$27,11,IF($B12="A",15,14)),INDEX('R3'!$D$3:$U$27,11,IF($B12="A",15,14))),"") | E12: =IF(OR(C12="",D12=""),"",D12-C12) | F12: =IFERROR(AVERAGE(INDEX('R1'!$D$3:$U$27,11,IF($B12="A",16,17)),INDEX('R2'!$D$3:$U$27,11,IF($B12="A",16,17)),INDEX('R3'!$D$3:$U$27,11,IF($B12="A",16,17))),"") | G12: =IFERROR(AVERAGE(INDEX('R1'!$D$3:$U$27,11,IF($B12="A",17,16)),INDEX('R2'!$D$3:$U$27,11,IF($B12="A",17,16)),INDEX('R3'!$D$3:$U$27,11,IF($B12="A",17,16))),"") | H12: =IF(OR(F12="",G12=""),"",G12-F12) | I12: =(INDEX('R1'!$D$3:$U$27,11,11)="Different")+(INDEX('R2'!$D$3:$U$27,11,11)="Different")+(INDEX('R3'!$D$3:$U$27,11,11)="Different") -> 0 | J12: =(INDEX('R1'!$D$3:$U$27,11,12)="Different")+(INDEX('R2'!$D$3:$U$27,11,12)="Different")+(INDEX('R3'!$D$3:$U$27,11,12)="Different") -> 0 | K12: =(INDEX('R1'!$D$3:$U$27,11,13)="Different")+(INDEX('R2'!$D$3:$U$27,11,13)="Different")+(INDEX('R3'!$D$3:$U$27,11,13)="Different") -> 0 | L12: =IF(C12="","",IF(OR(I12>=2,J12>=2,K12>=2),1,0))
A13: 12 | B13: =VLOOKUP(A13,'Blinding key'!$A$2:$G$26,7,FALSE()) -> B | C13: =IFERROR(AVERAGE(INDEX('R1'!$D$3:$U$27,12,IF($B13="A",14,15)),INDEX('R2'!$D$3:$U$27,12,IF($B13="A",14,15)),INDEX('R3'!$D$3:$U$27,12,IF($B13="A",14,15))),"") | D13: =IFERROR(AVERAGE(INDEX('R1'!$D$3:$U$27,12,IF($B13="A",15,14)),INDEX('R2'!$D$3:$U$27,12,IF($B13="A",15,14)),INDEX('R3'!$D$3:$U$27,12,IF($B13="A",15,14))),"") | E13: =IF(OR(C13="",D13=""),"",D13-C13) | F13: =IFERROR(AVERAGE(INDEX('R1'!$D$3:$U$27,12,IF($B13="A",16,17)),INDEX('R2'!$D$3:$U$27,12,IF($B13="A",16,17)),INDEX('R3'!$D$3:$U$27,12,IF($B13="A",16,17))),"") | G13: =IFERROR(AVERAGE(INDEX('R1'!$D$3:$U$27,12,IF($B13="A",17,16)),INDEX('R2'!$D$3:$U$27,12,IF($B13="A",17,16)),INDEX('R3'!$D$3:$U$27,12,IF($B13="A",17,16))),"") | H13: =IF(OR(F13="",G13=""),"",G13-F13) | I13: =(INDEX('R1'!$D$3:$U$27,12,11)="Different")+(INDEX('R2'!$D$3:$U$27,12,11)="Different")+(INDEX('R3'!$D$3:$U$27,12,11)="Different") -> 0 | J13: =(INDEX('R1'!$D$3:$U$27,12,12)="Different")+(INDEX('R2'!$D$3:$U$27,12,12)="Different")+(INDEX('R3'!$D$3:$U$27,12,12)="Different") -> 0 | K13: =(INDEX('R1'!$D$3:$U$27,12,13)="Different")+(INDEX('R2'!$D$3:$U$27,12,13)="Different")+(INDEX('R3'!$D$3:$U$27,12,13)="Different") -> 0 | L13: =IF(C13="","",IF(OR(I13>=2,J13>=2,K13>=2),1,0))
A14: 13 | B14: =VLOOKUP(A14,'Blinding key'!$A$2:$G$26,7,FALSE()) -> A | C14: =IFERROR(AVERAGE(INDEX('R1'!$D$3:$U$27,13,IF($B14="A",14,15)),INDEX('R2'!$D$3:$U$27,13,IF($B14="A",14,15)),INDEX('R3'!$D$3:$U$27,13,IF($B14="A",14,15))),"") | D14: =IFERROR(AVERAGE(INDEX('R1'!$D$3:$U$27,13,IF($B14="A",15,14)),INDEX('R2'!$D$3:$U$27,13,IF($B14="A",15,14)),INDEX('R3'!$D$3:$U$27,13,IF($B14="A",15,14))),"") | E14: =IF(OR(C14="",D14=""),"",D14-C14) | F14: =IFERROR(AVERAGE(INDEX('R1'!$D$3:$U$27,13,IF($B14="A",16,17)),INDEX('R2'!$D$3:$U$27,13,IF($B14="A",16,17)),INDEX('R3'!$D$3:$U$27,13,IF($B14="A",16,17))),"") | G14: =IFERROR(AVERAGE(INDEX('R1'!$D$3:$U$27,13,IF($B14="A",17,16)),INDEX('R2'!$D$3:$U$27,13,IF($B14="A",17,16)),INDEX('R3'!$D$3:$U$27,13,IF($B14="A",17,16))),"") | H14: =IF(OR(F14="",G14=""),"",G14-F14) | I14: =(INDEX('R1'!$D$3:$U$27,13,11)="Different")+(INDEX('R2'!$D$3:$U$27,13,11)="Different")+(INDEX('R3'!$D$3:$U$27,13,11)="Different") -> 0 | J14: =(INDEX('R1'!$D$3:$U$27,13,12)="Different")+(INDEX('R2'!$D$3:$U$27,13,12)="Different")+(INDEX('R3'!$D$3:$U$27,13,12)="Different") -> 0 | K14: =(INDEX('R1'!$D$3:$U$27,13,13)="Different")+(INDEX('R2'!$D$3:$U$27,13,13)="Different")+(INDEX('R3'!$D$3:$U$27,13,13)="Different") -> 0 | L14: =IF(C14="","",IF(OR(I14>=2,J14>=2,K14>=2),1,0))
A15: 14 | B15: =VLOOKUP(A15,'Blinding key'!$A$2:$G$26,7,FALSE()) -> B | C15: =IFERROR(AVERAGE(INDEX('R1'!$D$3:$U$27,14,IF($B15="A",14,15)),INDEX('R2'!$D$3:$U$27,14,IF($B15="A",14,15)),INDEX('R3'!$D$3:$U$27,14,IF($B15="A",14,15))),"") | D15: =IFERROR(AVERAGE(INDEX('R1'!$D$3:$U$27,14,IF($B15="A",15,14)),INDEX('R2'!$D$3:$U$27,14,IF($B15="A",15,14)),INDEX('R3'!$D$3:$U$27,14,IF($B15="A",15,14))),"") | E15: =IF(OR(C15="",D15=""),"",D15-C15) | F15: =IFERROR(AVERAGE(INDEX('R1'!$D$3:$U$27,14,IF($B15="A",16,17)),INDEX('R2'!$D$3:$U$27,14,IF($B15="A",16,17)),INDEX('R3'!$D$3:$U$27,14,IF($B15="A",16,17))),"") | G15: =IFERROR(AVERAGE(INDEX('R1'!$D$3:$U$27,14,IF($B15="A",17,16)),INDEX('R2'!$D$3:$U$27,14,IF($B15="A",17,16)),INDEX('R3'!$D$3:$U$27,14,IF($B15="A",17,16))),"") | H15: =IF(OR(F15="",G15=""),"",G15-F15) | I15: =(INDEX('R1'!$D$3:$U$27,14,11)="Different")+(INDEX('R2'!$D$3:$U$27,14,11)="Different")+(INDEX('R3'!$D$3:$U$27,14,11)="Different") -> 0 | J15: =(INDEX('R1'!$D$3:$U$27,14,12)="Different")+(INDEX('R2'!$D$3:$U$27,14,12)="Different")+(INDEX('R3'!$D$3:$U$27,14,12)="Different") -> 0 | K15: =(INDEX('R1'!$D$3:$U$27,14,13)="Different")+(INDEX('R2'!$D$3:$U$27,14,13)="Different")+(INDEX('R3'!$D$3:$U$27,14,13)="Different") -> 0 | L15: =IF(C15="","",IF(OR(I15>=2,J15>=2,K15>=2),1,0))
A16: 15 | B16: =VLOOKUP(A16,'Blinding key'!$A$2:$G$26,7,FALSE()) -> B | C16: =IFERROR(AVERAGE(INDEX('R1'!$D$3:$U$27,15,IF($B16="A",14,15)),INDEX('R2'!$D$3:$U$27,15,IF($B16="A",14,15)),INDEX('R3'!$D$3:$U$27,15,IF($B16="A",14,15))),"") | D16: =IFERROR(AVERAGE(INDEX('R1'!$D$3:$U$27,15,IF($B16="A",15,14)),INDEX('R2'!$D$3:$U$27,15,IF($B16="A",15,14)),INDEX('R3'!$D$3:$U$27,15,IF($B16="A",15,14))),"") | E16: =IF(OR(C16="",D16=""),"",D16-C16) | F16: =IFERROR(AVERAGE(INDEX('R1'!$D$3:$U$27,15,IF($B16="A",16,17)),INDEX('R2'!$D$3:$U$27,15,IF($B16="A",16,17)),INDEX('R3'!$D$3:$U$27,15,IF($B16="A",16,17))),"") | G16: =IFERROR(AVERAGE(INDEX('R1'!$D$3:$U$27,15,IF($B16="A",17,16)),INDEX('R2'!$D$3:$U$27,15,IF($B16="A",17,16)),INDEX('R3'!$D$3:$U$27,15,IF($B16="A",17,16))),"") | H16: =IF(OR(F16="",G16=""),"",G16-F16) | I16: =(INDEX('R1'!$D$3:$U$27,15,11)="Different")+(INDEX('R2'!$D$3:$U$27,15,11)="Different")+(INDEX('R3'!$D$3:$U$27,15,11)="Different") -> 0 | J16: =(INDEX('R1'!$D$3:$U$27,15,12)="Different")+(INDEX('R2'!$D$3:$U$27,15,12)="Different")+(INDEX('R3'!$D$3:$U$27,15,12)="Different") -> 0 | K16: =(INDEX('R1'!$D$3:$U$27,15,13)="Different")+(INDEX('R2'!$D$3:$U$27,15,13)="Different")+(INDEX('R3'!$D$3:$U$27,15,13)="Different") -> 0 | L16: =IF(C16="","",IF(OR(I16>=2,J16>=2,K16>=2),1,0))
A17: 16 | B17: =VLOOKUP(A17,'Blinding key'!$A$2:$G$26,7,FALSE()) -> B | C17: =IFERROR(AVERAGE(INDEX('R1'!$D$3:$U$27,16,IF($B17="A",14,15)),INDEX('R2'!$D$3:$U$27,16,IF($B17="A",14,15)),INDEX('R3'!$D$3:$U$27,16,IF($B17="A",14,15))),"") | D17: =IFERROR(AVERAGE(INDEX('R1'!$D$3:$U$27,16,IF($B17="A",15,14)),INDEX('R2'!$D$3:$U$27,16,IF($B17="A",15,14)),INDEX('R3'!$D$3:$U$27,16,IF($B17="A",15,14))),"") | E17: =IF(OR(C17="",D17=""),"",D17-C17) | F17: =IFERROR(AVERAGE(INDEX('R1'!$D$3:$U$27,16,IF($B17="A",16,17)),INDEX('R2'!$D$3:$U$27,16,IF($B17="A",16,17)),INDEX('R3'!$D$3:$U$27,16,IF($B17="A",16,17))),"") | G17: =IFERROR(AVERAGE(INDEX('R1'!$D$3:$U$27,16,IF($B17="A",17,16)),INDEX('R2'!$D$3:$U$27,16,IF($B17="A",17,16)),INDEX('R3'!$D$3:$U$27,16,IF($B17="A",17,16))),"") | H17: =IF(OR(F17="",G17=""),"",G17-F17) | I17: =(INDEX('R1'!$D$3:$U$27,16,11)="Different")+(INDEX('R2'!$D$3:$U$27,16,11)="Different")+(INDEX('R3'!$D$3:$U$27,16,11)="Different") -> 0 | J17: =(INDEX('R1'!$D$3:$U$27,16,12)="Different")+(INDEX('R2'!$D$3:$U$27,16,12)="Different")+(INDEX('R3'!$D$3:$U$27,16,12)="Different") -> 0 | K17: =(INDEX('R1'!$D$3:$U$27,16,13)="Different")+(INDEX('R2'!$D$3:$U$27,16,13)="Different")+(INDEX('R3'!$D$3:$U$27,16,13)="Different") -> 0 | L17: =IF(C17="","",IF(OR(I17>=2,J17>=2,K17>=2),1,0))
